Workbook

Sheet Lifestyle
A1: Standard Rates
A3: 50sqm Concrete paving | BB3: =50*140 -> 7000 | BD3: Bonus will be reviewed in August 2025 | BH3: Stormy line prices to be the same as sewer. | BM3: Delete bank of draws from vanities
A4: Floor tiles | BB4: 103 | BD4: Up to 24 sq | BE4: 3000 | BH4: Price accordingly in March
A5: Carpets | BB5: 60 | BD5: Above 24 sq | BE5: 4000 | BH5: Keep ordering at the same rate for now
A6: Eaves | BB6: 85 | BH6: Neopower Heat pump 315L as standard
A7: Price rise allowance | BB7: 0
BB9: Shepparton | BC9: Echuca | BO9: Lifestyle
BB10: 6 Months | BC10: 6 Months | BD10: Bonus | BF10: Floor Tiles | BG10: Wastage | BI10: Carpets | BJ10: Wastage | BL10: Eaves | BM10: Total area | BN10: List price | BO10: per m2
AE11: Windows | AO11: Sliding doors | AV11: Built-in robes/linens
A12: Single storey | B12: Dwelling area | C12: Garage area | D12: Porch area | E12: Outdoor living area | F12: Porch concrete footing | G12: Outdoor living footing | H12: Brick pier | I12: 90x90 steel columns | J12: Eaves | K12: Hip length | L12: Valley length | M12: Ridge length | N12: Perimeter walls | O12: Internal walls | P12: Plaster bulkheads | Q12: Kitchen wall bench | R12: Kitchen overhead cupboard | S12: Kitchen island bench | T12: Ens vanity bench | U12: Ens vanity basin | V12: Bath vanity bench | W12: Bath vanity basin | X12: Extra vanity bench | Y12: Extra vanity basin | Z12: Laundry bench | AA12: Internal swing door | AB12: Internal double swing door | AC12: Internal cavity sliders | AD12: Internal double cavity slider | AE12: 1006 | AF12: 1212 | AG12: 1215 | AH12: 1809 | AI12: 1812 | AJ12: 1818 | AK12: 1821 | AL12: 1824 | AM12: External swing door Entry | AN12: External swing door Garage | AO12: 2115 | AP12: 2118 | AQ12: 2121 | AR12: 2124 | AS12: 2127 | AT12: 2136 | AU12: 2155 | AV12: Up to 1800mm wide | AW12: 1800mm to 2500mm wide | AX12: 2500mm to 3000mm wide | AY12: Linen shelving - 4 shelves | AZ12: Robe shelving wth hanging rail | BA12: End panels
B13: m2 | C13: m2 | D13: m2 | E13: m2 | F13: lm | G13: lm | H13: each | I13: each | J13: lm | K13: lm | L13: lm | M13: lm | N13: lm | O13: lm | P13: lm | Q13: lm | R13: lm | S13: lm | T13: lm | U13: each | V13: lm | W13: each | X13: lm | Y13: each | Z13: lm | AA13: each | AB13: each | AC13: each | AD13: each | AE13: each | AF13: each | AG13: each | AH13: each | AI13: each | AJ13: each | AK13: each | AL13: each | AM13: each | AN13: each | AO13: each | AP13: each | AQ13: each | AR13: each | AS13: each | AT13: each | AU13: each | AV13: each | AW13: each | AX13: each | AY13: each | AZ13: each | BA13: each
A14: Adelaide 18 | B14: 120.71 | C14: 38.81 | D14: 5.06 | E14: 9.51 | F14: 3.8 | G14: 6.4 | H14: 1 | I14: 1 | J14: 7.09 | K14: 35.223 | L14: 9.003 | M14: 12.45 | N14: 45.17 | O14: 50.8 | P14: 3.16 | Q14: 1.5 | R14: 1.5 | S14: 2.4 | T14: 0.9 | U14: 1 | V14: 0.9 | W14: 1 | X14: 0 | Y14: 0 | Z14: 1.2 | AA14: 9 | AB14: 0 | AC14: 0 | AD14: 0 | AE14: 1 | AF14: 1 | AG14: 2 | AJ14: 1 | AP14: 1 | BB14: 279204 | BC14: 292541 | BD14: 3000 | BE14: =+BC14-BB14 -> 13337 | BF14: 44.2 | BG14: 1.1 | BH14: =+BG14*BF14 -> 48.62 | BI14: 42.17 | BJ14: 1.1 | BK14: =+BJ14*BI14 -> 46.387 | BL14: 52 | BM14: 174.08 | BN14: =+Shepparton!F4-Shepparton!C4 -> 290005 | BO14: =+ROUND(BN14/BM14,) -> 1666
A15: Adelaide 21 | B15: 142.05 | C15: 38.79 | D15: 5.06 | E15: 10.31 | H15: 1 | J15: 7.09 | K15: 35.226 | L15: 9.003 | M15: 14.97 | N15: 50.21 | O15: 54.65 | P15: 3.16 | Q15: 1.43 | R15: 1.43 | S15: 2.35 | T15: 0.9 | U15: 1 | V15: 0.9 | W15: 1 | X15: 0 | Y15: 0 | Z15: 1.2 | BB15: 293633 | BC15: 306971 | BD15: 3000 | BE15: =+BC15-BB15 -> 13338 | BF15: 45.36 | BG15: 1.1 | BH15: =+BG15*BF15 -> 49.896 | BI15: 62.1 | BJ15: 1.1 | BK15: =+BJ15*BI15 -> 68.31 | BL15: 57 | BM15: 196.26 | BN15: =+Shepparton!F5-Shepparton!C5 -> 305880 | BO15: =+ROUND(BN15/BM15,) -> 1559
A16: Adelaide 22A | B16: 154.9 | C16: 38.57 | D16: 4.18 | E16: 11.61 | H16: 2 | J16: 5.965 | K16: 37.711 | L16: 10.26 | M16: 15.34 | N16: 51.73 | O16: 64.2 | P16: 2.8 | Q16: 3.1 | R16: 1.9 | S16: 2.5 | T16: 1.2 | U16: 1 | V16: 0.9 | W16: 1 | X16: 0 | Y16: 0 | Z16: 1.2 | BB16: 307717 | BC16: 320996 | BD16: 3000 | BE16: =+BC16-BB16 -> 13279 | BF16: 52.38 | BG16: 1.1 | BH16: =+BG16*BF16 -> 57.618 | BI16: 61.84 | BJ16: 1.1 | BK16: =+BJ16*BI16 -> 68.024 | BL16: 60 | BM16: 209.25 | BN16: =+Shepparton!F6-Shepparton!C6 -> 320740 | BO16: =+ROUND(BN16/BM16,) -> 1533
A17: Adelaide 22B | B17: 154.9 | C17: 38.57 | D17: 4.18 | E17: 11.66 | H17: 2 | J17: 5.965 | K17: 37.711 | L17: 10.26 | M17: 15.34 | N17: 51.73 | O17: 68.35 | P17: 2.8 | Q17: 3.1 | R17: 1.9 | S17: 2.5 | T17: 1.2 | U17: 1 | V17: 0.9 | W17: 1 | X17: 0 | Y17: 0 | Z17: 1.2 | BB17: 309383 | BC17: 322640 | BD17: 3000 | BE17: =+BC17-BB17 -> 13257 | BF17: 51.94 | BG17: 1.1 | BH17: =+BG17*BF17 -> 57.134 | BI17: 60.31 | BJ17: 1.1 | BK17: =+BJ17*BI17 -> 66.341 | BL17: 60 | BM17: 209.25 | BN17: =+Shepparton!F7-Shepparton!C7 -> 322260 | BO17: =+ROUND(BN17/BM17,) -> 1540
A18: Adelaide 24 | B18: 170.21 | C18: 38.68 | D18: 5.08 | E18: 11.92 | H18: 1 | J18: 7.09 | K18: 37.32 | L18: 9.002 | M18: 15.66 | N18: 55.29 | O18: 67.25 | P18: 3.9 | Q18: 2.08 | R18: 2.08 | S18: 2.7 | T18: 0.9 | U18: 1 | V18: 0.9 | W18: 1 | X18: 0 | Y18: 0 | Z18: 1.2 | BB18: 316962 | BC18: 330230 | BD18: 3000 | BE18: =+BC18-BB18 -> 13268 | BF18: 56.63 | BG18: 1.1 | BH18: =+BG18*BF18 -> 62.293 | BI18: 75.55 | BJ18: 1.1 | BK18: =+BJ18*BI18 -> 83.105 | BL18: 62 | BM18: 225.88 | BN18: =+Shepparton!F8-Shepparton!C8 -> 331380 | BO18: =+ROUND(BN18/BM18,) -> 1467
A19: Ashfield 24 | B19: 269.78 | C19: 41.25 | D19: 6.32 | E19: 13.24 | H19: 3 | J19: 6.69 | K19: 41.9 | L19: 9.02 | M19: 11.26 | N19: 51.01 | O19: 75.35 | P19: 3.75 | Q19: 2.75 | R19: 2.75 | S19: 2.7 | T19: 0.9 | U19: 1 | V19: 0.9 | W19: 1 | X19: 0 | Y19: 0 | Z19: 1.2 | BB19: 319218 | BC19: 332578 | BD19: 3000 | BE19: =+BC19-BB19 -> 13360 | BF19: 76.52 | BG19: 1.1 | BH19: =+BG19*BF19 -> 84.172 | BI19: 52.6 | BJ19: 1.1 | BK19: =+BJ19*BI19 -> 57.86 | BL19: 58 | BM19: 230.2 | BN19: =+Shepparton!F9-Shepparton!C9 -> 334365 | BO19: =+ROUND(BN19/BM19,) -> 1452
A20: Ashfield 30 | B20: 201.44 | C20: 41.23 | D20: 7.14 | E20: 28.76 | H20: 4 | J20: 6.635 | K20: 45.2 | L20: 22.53 | M20: 20.6 | N20: 55.19 | O20: 92.7 | P20: 6.78 | Q20: 2.75 | R20: 2.75 | S20: 2.7 | T20: 0.9 | U20: 1 | V20: 0.9 | W20: 1 | X20: 1.2 | Y20: 1 | Z20: 1.2 | BB20: 355577 | BC20: 368840 | BD20: 4000 | BE20: =+BC20-BB20 -> 13263 | BF20: 70.06 | BG20: 1.1 | BH20: =+BG20*BF20 -> 77.066 | BI20: 84.94 | BJ20: 1.1 | BK20: =+BJ20*BI20 -> 93.434 | BL20: 60 | BM20: 278.55 | BN20: =+Shepparton!F10-Shepparton!C10 -> 373130 | BO20: =+ROUND(BN20/BM20,) -> 1340
A21: Ashfield 34 | B21: 228.94 | C21: 41.16 | D21: 7.38 | E21: 37.68 | H21: 4 | J21: 6.64 | K21: 47.261 | L21: 25.68 | M21: 24.465 | N21: 60 | O21: 101 | P21: 6.7 | Q21: 2.85 | R21: 2.85 | S21: 2.7 | T21: 0.9 | U21: 1 | V21: 0.9 | W21: 1 | X21: 1.33 | Y21: 1 | Z21: 1.2 | BB21: 382148 | BC21: 395470 | BD21: 4000 | BE21: =+BC21-BB21 -> 13322 | BF21: 74.45 | BG21: 1.1 | BH21: =+BG21*BF21 -> 81.895 | BI21: 101.45 | BJ21: 1.1 | BK21: =+BJ21*BI21 -> 111.595 | BL21: 74 | BM21: 315.15 | BN21: =+Shepparton!F11-Shepparton!C11 -> 401290 | BO21: =+ROUND(BN21/BM21,) -> 1273
A22: Ashley 19 | B22: 126.99 | C22: 38.55 | D22: 5.03 | E22: 9.24 | H22: 2 | J22: 6.08 | K22: 40.75 | L22: 10.6 | M22: 9.32 | N22: 44.06 | O22: 51.35 | P22: 4.06 | Q22: 2.24 | R22: 2.24 | S22: 2.7 | T22: 0.9 | U22: 1 | V22: 0.9 | W22: 1 | X22: 0 | Y22: 0 | Z22: 1.2 | BB22: 277619 | BC22: 290856 | BD22: 3000 | BE22: =+BC22-BB22 -> 13237 | BF22: 51.21 | BG22: 1.1 | BH22: =+BG22*BF22 -> 56.331 | BI22: 42.5 | BJ22: 1.1 | BK22: =+BJ22*BI22 -> 46.75 | BL22: 51 | BM22: 179.82 | BN22: =+Shepparton!F12-Shepparton!C12 -> 289230 | BO22: =+ROUND(BN22/BM22,) -> 1608
A23: Ashley 21 | BB23: 297059 | BC23: 309921 | BD23: 3000 | BE23: =+BC23-BB23 -> 12862 | BF23: 61.52 | BG23: 1.1 | BH23: =+BG23*BF23 -> 67.672 | BI23: 56.58 | BJ23: 1.1 | BK23: =+BJ23*BI23 -> 62.238 | BL23: 59
A24: Ashley 22 | B24: 155.58 | C24: 37.55 | D24: 4.13 | E24: 10.65 | H24: 2 | J24: 6.9 | K24: 41.15 | L24: 11.14 | M24: 11.64 | N24: 48.69 | O24: 66.87 | P24: 2.7 | Q24: 1.8 | R24: 1.8 | S24: 2.7 | T24: 0.9 | U24: 1 | V24: 0.9 | W24: 1 | X24: 0 | Y24: 0 | Z24: 1.2 | BB24: 294577 | BC24: 307545 | BD24: 3000 | BE24: =+BC24-BB24 -> 12968 | BF24: 60.5 | BG24: 1.1 | BH24: =+BG24*BF24 -> 66.55 | BI24: 58.66 | BJ24: 1.1 | BK24: =+BJ24*BI24 -> 64.526 | BL24: 56 | BM24: 207.9 | BN24: =+Shepparton!F14-Shepparton!C14 -> 308310 | BO24: =+ROUND(BN24/BM24,) -> 1483
A25: Ashley 22A | BB25: 300718 | BC25: 313916 | BD25: 3000 | BE25: =+BC25-BB25 -> 13198 | BF25: 65.93 | BG25: 1.1 | BH25: =+BG25*BF25 -> 72.523 | BI25: 54.72 | BJ25: 1.1 | BK25: =+BJ25*BI25 -> 60.192 | BL25: 56
A26: Ashley 24 | B26: 164 | C26: 38.5 | D26: 4.99 | E26: 16.12 | H26: 2 | J26: 6.7 | K26: 41.54 | L26: 10.814 | M26: 13.1 | N26: 52 | O26: 65.9 | P26: 2.8 | Q26: 1.9 | R26: 1.9 | S26: 2.7 | T26: 0.9 | U26: 1 | V26: 0.9 | W26: 1 | X26: 0 | Y26: 0 | Z26: 1.2 | BB26: 312046 | BC26: 325561 | BD26: 3000 | BE26: =+BC26-BB26 -> 13515 | BF26: 57.4 | BG26: 1.1 | BH26: =+BG26*BF26 -> 63.14 | BI26: 70.61 | BJ26: 1.1 | BK26: =+BJ26*BI26 -> 77.671 | BL26: 59 | BM26: 223.46 | BN26: =+Shepparton!F16-Shepparton!C16 -> 326220 | BO26: =+ROUND(BN26/BM26,) -> 1460
A27: Ashley 25 | B27: 170.72 | C27: 38.42 | D27: 4.52 | E27: 21 | H27: 2 | J27: 6.18 | K27: 49.79 | L27: 19.185 | M27: 15.49 | N27: 50.35 | O27: 73.15 | P27: 5.08 | Q27: 4.18 | R27: 4.18 | S27: 3 | T27: 0.9 | U27: 1 | V27: 0.9 | W27: 1 | X27: 0 | Y27: 0 | Z27: 1.2 | BB27: 320081 | BC27: 333403 | BD27: 4000 | BE27: =+BC27-BB27 -> 13322 | BF27: 61.33 | BG27: 1.1 | BH27: =+BG27*BF27 -> 67.463 | BI27: 69.8 | BJ27: 1.1 | BK27: =+BJ27*BI27 -> 76.78 | BL27: 64 | BM27: 234.65 | BN27: =+Shepparton!F17-Shepparton!C17 -> 335650 | BO27: =+ROUND(BN27/BM27,) -> 1430
A28: Ashley 25A | B28: 172.94 | C28: 37.49 | D28: 4.52 | E28: 21 | H28: 3 | J28: 6.18 | K28: 49.79 | L28: 19.185 | M28: 15.49 | N28: 50.35 | O28: 73.15 | P28: 5.08 | Q28: 3.3 | R28: 1.9 | S28: 3.6 | T28: 0.9 | U28: 1 | V28: 0.9 | W28: 1 | X28: 0 | Y28: 0 | Z28: 1.2 | BB28: 330229 | BC28: 343545 | BD28: 4000 | BE28: =+BC28-BB28 -> 13316 | BF28: 62.1 | BG28: 1.1 | BH28: =+BG28*BF28 -> 68.31 | BI28: 70.48 | BJ28: 1.1 | BK28: =+BJ28*BI28 -> 77.528 | BL28: 64 | BM28: 235.95 | BN28: =+Shepparton!F18-Shepparton!C18 -> 345925 | BO28: =+ROUND(BN28/BM28,) -> 1466
A29: Ashley 26 | B29: 175.05 | C29: 38.43 | D29: 7.67 | E29: 20.53 | H29: 2 | J29: 4.44 | K29: 48.14 | L29: 16.61 | M29: 14 | N29: 53.05 | O29: 69.15 | P29: 3.36 | Q29: 2.46 | R29: 2.46 | S29: 3 | T29: 1.2 | U29: 1 | V29: 0.9 | W29: 1 | X29: 0 | Y29: 0 | Z29: 0 | BB29: 326973 | BC29: 340209 | BD29: 4000 | BE29: =+BC29-BB29 -> 13236 | BF29: 62.2 | BG29: 1.1 | BH29: =+BG29*BF29 -> 68.42 | BI29: 74.19 | BJ29: 1.1 | BK29: =+BJ29*BI29 -> 81.609 | BL29: 62 | BM29: 241.67 | BN29: =+Shepparton!F19-Shepparton!C19 -> 342930 | BO29: =+ROUND(BN29/BM29,) -> 1419
A30: Ashley 27 | B30: 195.53 | C30: 38.38 | D30: 4.97 | E30: 15.996 | H30: 2 | J30: 6.18 | K30: 41.138 | L30: 10.814 | M30: 16.47 | N30: 58.28 | O30: 81.85 | P30: 3.22 | Q30: 2.312 | R30: 2.312 | S30: 2.7 | T30: 0.9 | U30: 1 | V30: 0.9 | W30: 1 | X30: 0 | Y30: 0 | Z30: 1.2 | BB30: 338903 | BC30: 352214 | BD30: 4000 | BE30: =+BC30-BB30 -> 13311 | BF30: 70.54 | BG30: 1.1 | BH30: =+BG30*BF30 -> 77.594 | BI30: 92.05 | BJ30: 1.1 | BK30: =+BJ30*BI30 -> 101.255 | BL30: 65 | BM30: 254.89 | BN30: =+Shepparton!F20-Shepparton!C20 -> 356985 | BO30: =+ROUND(BN30/BM30,) -> 1401
A31: Ashley 28 | B31: 193.91 | C31: 38.67 | D31: 7.19 | E31: 19.61 | H31: 2 | J31: 5.26 | K31: 42.66 | L31: 12.891 | M31: 17.025 | N31: 58.25 | O31: 79.65 | P31: 3.27 | Q31: 2.42 | R31: 2.42 | S31: 2.7 | T31: 1.8 | U31: 2 | V31: 0.9 | W31: 1 | X31: 0 | Y31: 0 | Z31: 1.2 | BB31: 343732 | BC31: 356760 | BD31: 4000 | BE31: =+BC31-BB31 -> 13028 | BF31: 78.48 | BG31: 1.1 | BH31: =+BG31*BF31 -> 86.328 | BI31: 66.52 | BJ31: 1.1 | BK31: =+BJ31*BI31 -> 73.172 | BL31: 65 | BM31: 258.33 | BN31: =+Shepparton!F21-Shepparton!C21 -> 361030 | BO31: =+ROUND(BN31/BM31,) -> 1398
A32: Ashley 28A | BB32: 351250 | BC32: 364509 | BD32: 4000 | BE32: =+BC32-BB32 -> 13259 | BF32: 82.36 | BG32: 1.1 | BH32: =+BG32*BF32 -> 90.596 | BI32: 88.36 | BJ32: 1.1 | BK32: =+BJ32*BI32 -> 97.196 | BL32: 65 | BM32: 258.33 | BN32: =+Shepparton!F22-Shepparton!C22 -> 370420 | BO32: =+ROUND(BN32/BM32,) -> 1434
A33: Ballina 24 | B33: 156.97 | C33: 40.42 | D33: 2.83 | E33: 21.22 | H33: 1 | J33: 6.5 | K33: 50.1 | L33: 11.5 | M33: 2 | N33: 47 | O33: 82.6 | P33: 6.9 | Q33: 4.4 | R33: 2.2 | S33: 2.5 | T33: 1.2 | U33: 1 | V33: 0.9 | W33: 1 | X33: 0 | Y33: 0 | Z33: 1.2 | BB33: 312597 | BC33: 325831 | BD33: 3000 | BE33: =+BC33-BB33 -> 13234 | BF33: 70.31 | BG33: 1.1 | BH33: =+BG33*BF33 -> 77.341 | BI33: 45.65 | BJ33: 1.1 | BK33: =+BJ33*BI33 -> 50.215 | BL33: 53 | BM33: 221.43 | BN33: =+Shepparton!F23-Shepparton!C23 -> 326585 | BO33: =+ROUND(BN33/BM33,) -> 1475
A34: Ballina 30 | B34: 209.74 | C34: 37.6 | D34: 2.86 | E34: 23.77 | H34: 3 | J34: 10.3 | K34: 49 | L34: 17.9 | M34: 16.8 | N34: 57.2 | O34: 95 | P34: 11.3 | Q34: 4.4 | R34: 2.5 | S34: 0 | T34: 1.2 | U34: 1 | V34: 0.9 | W34: 1 | X34: 0 | Y34: 0 | Z34: 1.2 | BB34: 360743 | BC34: 373971 | BD34: 4000 | BE34: =+BC34-BB34 -> 13228 | BF34: 85.08 | BG34: 1.1 | BH34: =+BG34*BF34 -> 93.588 | BI34: 80.35 | BJ34: 1.1 | BK34: =+BJ34*BI34 -> 88.385 | BL34: 67 | BM34: 273.96 | BN34: =+Shepparton!F24-Shepparton!C24 -> 379695 | BO34: =+ROUND(BN34/BM34,) -> 1386
A35: Ballina 30A | BB35: 363040 | BC35: 376292 | BD35: 4000 | BE35: =+BC35-BB35 -> 13252 | BF35: 95 | BG35: 1.1 | BH35: =+BG35*BF35 -> 104.5 | BI35: 86 | BJ35: 1.1 | BK35: =+BJ35*BI35 -> 94.6 | BL35: 70 | BM35: 275.39 | BN35: =+Shepparton!F25-Shepparton!C25 -> 383485 | BO35: =+ROUND(BN35/BM35,) -> 1393
A36: Ballina 33 | B36: 240.4 | C36: 38.21 | D36: 2.43 | E36: 30.1 | H36: 1 | J36: 5.6 | K36: 59.1 | L36: 24.1 | M36: 17.8 | N36: 60.9 | O36: 110.8 | P36: 9.6 | Q36: 4.5 | R36: 2.4 | S36: 2.7 | T36: 1.8 | U36: 2 | V36: 0.9 | W36: 1 | X36: 0.9 | Y36: 1 | Z36: 1.2 | BB36: 395086 | BC36: 408310 | BD36: 4000 | BE36: =+BC36-BB36 -> 13224 | BF36: 104.44 | BG36: 1.1 | BH36: =+BG36*BF36 -> 114.884 | BI36: 79.41 | BJ36: 1.1 | BK36: =+BJ36*BI36 -> 87.351 | BL36: 75 | BM36: 311.15 | BN36: =+Shepparton!F26-Shepparton!C26 -> 416170 | BO36: =+ROUND(BN36/BM36,) -> 1338
A37: Ballina 39 | B37: 290 | C37: 39.7 | D37: 2.64 | E37: 31.8 | H37: 3 | J37: 5.7 | K37: 62.8 | L37: 26.2 | M37: 20.3 | N37: 74.5 | O37: 135 | P37: 16.9 | Q37: 4 | R37: 2.5 | S37: 2.7 | T37: 2.3 | U37: 2 | V37: 0.9 | W37: 1 | X37: 0.9 | Y37: 1 | Z37: 1.2 | BB37: 440177 | BC37: 453342 | BD37: 4000 | BE37: =+BC37-BB37 -> 13165 | BF37: 117 | BG37: 1.1 | BH37: =+BG37*BF37 -> 128.7 | BI37: 117 | BJ37: 1.1 | BK37: =+BJ37*BI37 -> 128.7 | BL37: 80 | BM37: 364.15 | BN37: =+Shepparton!F27-Shepparton!C27 -> 465165 | BO37: =+ROUND(BN37/BM37,) -> 1277
A38: Bathurst 25 | BB38: 343405 | BC38: 356677 | BD38: 4000 | BE38: =+BC38-BB38 -> 13272 | BF38: =70.7/1.1 -> 64.272727 | BG38: 1.1 | BH38: =+BG38*BF38 -> 70.7 | BI38: =65.96/1.1 -> 59.963636 | BJ38: 1.1 | BK38: =+BJ38*BI38 -> 65.96 | BL38: 61 | BM38: 231.34 | BN38: =+Shepparton!F28-Shepparton!C28 -> 358655 | BO38: =+ROUND(BN38/BM38,) -> 1550
A39: Bathurst 30 | BB39: 390384 | BC39: 403713 | BD39: 4000 | BE39: =+BC39-BB39 -> 13329 | BF39: =85.22/1.1 -> 77.472727 | BG39: 1.1 | BH39: =+BG39*BF39 -> 85.22 | BI39: =93.9/1.1 -> 85.363636 | BJ39: 1.1 | BK39: =+BJ39*BI39 -> 93.9 | BL39: 70 | BM39: 284.15 | BN39: =+Shepparton!F29-Shepparton!C29 -> 408805 | BO39: =+ROUND(BN39/BM39,) -> 1439
A40: Bathurst 34 | BB40: 411473 | BC40: 422047 | BD40: 4000 | BE40: =+BC40-BB40 -> 10574 | BF40: =93.92/1.1 -> 85.381818 | BG40: 1.1 | BH40: =+BG40*BF40 -> 93.92 | BI40: =105.78/1.1 -> 96.163636 | BJ40: 1.1 | BK40: =+BJ40*BI40 -> 105.78 | BL40: 74 | BM40: 317.69 | BN40: =+Shepparton!F30-Shepparton!C30 -> 431505 | BO40: =+ROUND(BN40/BM40,) -> 1358
A41: Bayview 23 | B41: 154.7 | C41: 38.8 | D41: 5.88 | E41: 13.63 | H41: 1 | J41: 12.72 | K41: 51.381 | L41: 20.817 | M41: 13.47 | N41: 55.16 | O41: 57.7 | P41: 4.2 | Q41: 2.37 | R41: 2.37 | S41: 2.7 | T41: 0.9 | U41: 1 | V41: 0.9 | W41: 1 | X41: 0 | Y41: 0 | Z41: 1.2 | BB41: 313918 | BC41: 327135 | BD41: 3000 | BE41: =+BC41-BB41 -> 13217 | BF41: 71.87 | BG41: 1.1 | BH41: =+BG41*BF41 -> 79.057 | BI41: 45.5 | BJ41: 1.1 | BK41: =+BJ41*BI41 -> 50.05 | BL41: 56 | BM41: 212.95 | BN41: =+Shepparton!F31-Shepparton!C31 -> 328070 | BO41: =+ROUND(BN41/BM41,) -> 1541
A42: Bayview 26 | B42: 181.61 | C42: 38.82 | D42: 5.88 | E42: 17.38 | H42: 1 | J42: 12.77 | K42: 51.267 | L42: 20.239 | M42: 16.46 | N42: 60.98 | O42: 70.1 | P42: 4.2 | Q42: 2.37 | R42: 2.37 | S42: 2.7 | T42: 0.9 | U42: 1 | V42: 0.9 | W42: 1 | X42: 0 | Y42: 0 | Z42: 1.2 | BB42: 335864 | BC42: 349100 | BD42: 4000 | BE42: =+BC42-BB42 -> 13236 | BF42: 62.78 | BG42: 1.1 | BH42: =+BG42*BF42 -> 69.058 | BI42: 76.6 | BJ42: 1.1 | BK42: =+BJ42*BI42 -> 84.26 | BL42: 62 | BM42: 243.4 | BN42: =+Shepparton!F32-Shepparton!C32 -> 352045 | BO42: =+ROUND(BN42/BM42,) -> 1446
...

Sheet Landscaping
C5: Seed | D5: Turf | E5: Turf with excavation
B6: 600m2 | C6: 14154.02 | D6: 16686.01 | E6: 18542.01 | H6: =+D6-C6 -> 2531.99 | J6: =+E6-D6 -> 1856
B7: 800m2 | C7: 17723.13 | D7: 21199.93 | E7: 23055.26 | H7: =+D7-C7 -> 3476.8 | J7: =+E7-D7 -> 1855.33
B8: Nature strip | E8: 1918.24
B9: Corner block | E9: 3841.6
B10: External power point | E10: =+Electrical!D11 -> 135
C13: Seed | D13: Turf
B14: 600m2 normal block | C14: =CEILING((C6+J6+E8)*1.36,50)+E10 -> 24535 | D14: =CEILING((E6+E8)*1.36,25)+E10 -> 27985
B15: 600m2 corner block | C15: =+CEILING((C6+J6+E9)*1.36,25)+E10 -> 27135 | D15: =+CEILING((E6+E9)*1.36,25)+E10 -> 30585
B16: 800m2 normal block | C16: =+CEILING((C7+J6+E8)*1.36,25)+E10 -> 29385 | D16: =+CEILING((E7+E8)*1.36,25)+E10 -> 34110
B17: 800m2 corner block | C17: =+CEILING((C7+E9+J6)*1.36,25)+E10 -> 32010 | D17: =+CEILING((E7+E9)*1.36,25)+E10 -> 36735

Sheet Shepparton
A1: SHEPPARTON
A2: LIFESTYLE SINGLE STOREY PRICE LIST VALID UP TO AUG 2025
A3: HOUSE DESIGN | B3: BASE PRICE * | C3: 50sqm NATURAL CONCRETE | D3: LIFESTYLE FLOOR TILES | E3: LIFESTYLE CARPETS | F3: PACKAGE PRICE *50sqm NATURAL CONCRETE *CARPET *TILES | G3: PRICE TO ADD EAVES | I3: List price | J3: Promotional | K3: Bonus | L3: 50sqm natural concrete | M3: Tiles per sqm | N3: Carpet per sqm | O3: Eaves per lm
A4: Adelaide 18 | B4: =+CEILING(I4+J4+K4,10) -> 282210 | C4: =+L4 -> 7000 | D4: =+CEILING(Lifestyle!BH14*Shepparton!M4,5) -> 5010 | E4: =+CEILING(Lifestyle!BK14*Shepparton!N4,5) -> 2785 | F4: =SUM(B4:E4) -> 297005 | G4: =+CEILING(Lifestyle!BL14*Shepparton!O4,5) -> 4420 | I4: =+Lifestyle!BB14 -> 279204 | J4: =+Lifestyle!BB7 -> 0 | K4: =+Lifestyle!BD14 -> 3000 | L4: =+Lifestyle!BB3 -> 7000 | M4: =+Lifestyle!BB4 -> 103 | N4: =+Lifestyle!BB5 -> 60 | O4: =+Lifestyle!BB6 -> 85
A5: Adelaide 21 | B5: =+CEILING(I5+J5+K5,10) -> 296640 | C5: =+L5 -> 7000 | D5: =+CEILING(Lifestyle!BH15*Shepparton!M5,5) -> 5140 | E5: =+CEILING(Lifestyle!BK15*Shepparton!N5,5) -> 4100 | F5: =SUM(B5:E5) -> 312880 | G5: =+CEILING(Lifestyle!BL15*Shepparton!O5,5) -> 4845 | I5: =+Lifestyle!BB15 -> 293633 | J5: =+J4 -> 0 | K5: =+Lifestyle!BD15 -> 3000 | L5: =+L4 -> 7000 | M5: =+M4 -> 103 | N5: =+N4 -> 60 | O5: =+O4 -> 85
A6: Adelaide 22A | B6: =+CEILING(I6+J6+K6,10) -> 310720 | C6: =+L6 -> 7000 | D6: =+CEILING(Lifestyle!BH16*Shepparton!M6,5) -> 5935 | E6: =+CEILING(Lifestyle!BK16*Shepparton!N6,5) -> 4085 | F6: =SUM(B6:E6) -> 327740 | G6: =+CEILING(Lifestyle!BL16*Shepparton!O6,5) -> 5100 | I6: =+Lifestyle!BB16 -> 307717 | J6: =+J5 -> 0 | K6: =+Lifestyle!BD16 -> 3000 | L6: =+L5 -> 7000 | M6: =+M5 -> 103 | N6: =+N5 -> 60 | O6: =+O5 -> 85
A7: Adelaide 22B | B7: =+CEILING(I7+J7+K7,10) -> 312390 | C7: =+L7 -> 7000 | D7: =+CEILING(Lifestyle!BH17*Shepparton!M7,5) -> 5885 | E7: =+CEILING(Lifestyle!BK17*Shepparton!N7,5) -> 3985 | F7: =SUM(B7:E7) -> 329260 | G7: =+CEILING(Lifestyle!BL17*Shepparton!O7,5) -> 5100 | I7: =+Lifestyle!BB17 -> 309383 | J7: =+J6 -> 0 | K7: =+Lifestyle!BD17 -> 3000 | L7: =+L6 -> 7000 | M7: =+M6 -> 103 | N7: =+N6 -> 60 | O7: =+O6 -> 85
A8: Adelaide 24 | B8: =+CEILING(I8+J8+K8,10) -> 319970 | C8: =+L8 -> 7000 | D8: =+CEILING(Lifestyle!BH18*Shepparton!M8,5) -> 6420 | E8: =+CEILING(Lifestyle!BK18*Shepparton!N8,5) -> 4990 | F8: =SUM(B8:E8) -> 338380 | G8: =+CEILING(Lifestyle!BL18*Shepparton!O8,5) -> 5270 | I8: =+Lifestyle!BB18 -> 316962 | J8: =+J7 -> 0 | K8: =+Lifestyle!BD18 -> 3000 | L8: =+L7 -> 7000 | M8: =+M7 -> 103 | N8: =+N7 -> 60 | O8: =+O7 -> 85
A9: Ashfield 24 | B9: =+CEILING(I9+J9+K9,10) -> 322220 | C9: =+L9 -> 7000 | D9: =+CEILING(Lifestyle!BH19*Shepparton!M9,5) -> 8670 | E9: =+CEILING(Lifestyle!BK19*Shepparton!N9,5) -> 3475 | F9: =SUM(B9:E9) -> 341365 | G9: =+CEILING(Lifestyle!BL19*Shepparton!O9,5) -> 4930 | I9: =+Lifestyle!BB19 -> 319218 | J9: =+J8 -> 0 | K9: =+Lifestyle!BD19 -> 3000 | L9: =+L8 -> 7000 | M9: =+M8 -> 103 | N9: =+N8 -> 60 | O9: =+O8 -> 85
A10: Ashfield 30 | B10: =+CEILING(I10+J10+K10,10) -> 359580 | C10: =+L10 -> 7000 | D10: =+CEILING(Lifestyle!BH20*Shepparton!M10,5) -> 7940 | E10: =+CEILING(Lifestyle!BK20*Shepparton!N10,5) -> 5610 | F10: =SUM(B10:E10) -> 380130 | G10: =+CEILING(Lifestyle!BL20*Shepparton!O10,5) -> 5100 | I10: =+Lifestyle!BB20 -> 355577 | J10: =+J9 -> 0 | K10: =+Lifestyle!BD20 -> 4000 | L10: =+L9 -> 7000 | M10: =+M9 -> 103 | N10: =+N9 -> 60 | O10: =+O9 -> 85
A11: Ashfield 34 | B11: =+CEILING(I11+J11+K11,10) -> 386150 | C11: =+L11 -> 7000 | D11: =+CEILING(Lifestyle!BH21*Shepparton!M11,5) -> 8440 | E11: =+CEILING(Lifestyle!BK21*Shepparton!N11,5) -> 6700 | F11: =SUM(B11:E11) -> 408290 | G11: =+CEILING(Lifestyle!BL21*Shepparton!O11,5) -> 6290 | I11: =+Lifestyle!BB21 -> 382148 | J11: =+J10 -> 0 | K11: =+Lifestyle!BD21 -> 4000 | L11: =+L10 -> 7000 | M11: =+M10 -> 103 | N11: =+N10 -> 60 | O11: =+O10 -> 85
A12: Ashley 19 | B12: =+CEILING(I12+J12+K12,10) -> 280620 | C12: =+L12 -> 7000 | D12: =+CEILING(Lifestyle!BH22*Shepparton!M12,5) -> 5805 | E12: =+CEILING(Lifestyle!BK22*Shepparton!N12,5) -> 2805 | F12: =SUM(B12:E12) -> 296230 | G12: =+CEILING(Lifestyle!BL22*Shepparton!O12,5) -> 4335 | I12: =+Lifestyle!BB22 -> 277619 | J12: =+J11 -> 0 | K12: =+Lifestyle!BD22 -> 3000 | L12: =+L11 -> 7000 | M12: =+M11 -> 103 | N12: =+N11 -> 60 | O12: =+O11 -> 85
A13: Ashley 21 | B13: =+CEILING(I13+J13+K13,10) -> 300060 | C13: =+L13 -> 7000 | D13: =+CEILING(Lifestyle!BH23*Shepparton!M13,5) -> 6975 | E13: =+CEILING(Lifestyle!BK23*Shepparton!N13,5) -> 3735 | F13: =SUM(B13:E13) -> 317770 | G13: =+CEILING(Lifestyle!BL23*Shepparton!O13,5) -> 5015 | I13: =+Lifestyle!BB23 -> 297059 | J13: =+J12 -> 0 | K13: =+Lifestyle!BD23 -> 3000 | L13: =+L12 -> 7000 | M13: =+M12 -> 103 | N13: =+N12 -> 60 | O13: =+O12 -> 85
A14: Ashley 22 | B14: =+CEILING(I14+J14+K14,10) -> 297580 | C14: =+L14 -> 7000 | D14: =+CEILING(Lifestyle!BH24*Shepparton!M14,5) -> 6855 | E14: =+CEILING(Lifestyle!BK24*Shepparton!N14,5) -> 3875 | F14: =SUM(B14:E14) -> 315310 | G14: =+CEILING(Lifestyle!BL24*Shepparton!O14,5) -> 4760 | I14: =+Lifestyle!BB24 -> 294577 | J14: =+J13 -> 0 | K14: =+Lifestyle!BD24 -> 3000 | L14: =+L13 -> 7000 | M14: =+M13 -> 103 | N14: =+N13 -> 60 | O14: =+O13 -> 85
A15: Ashley 22A | B15: =+CEILING(I15+J15+K15,10) -> 303720 | C15: =+L15 -> 7000 | D15: =+CEILING(Lifestyle!BH25*Shepparton!M15,5) -> 7470 | E15: =+CEILING(Lifestyle!BK25*Shepparton!N15,5) -> 3615 | F15: =SUM(B15:E15) -> 321805 | G15: =+CEILING(Lifestyle!BL25*Shepparton!O15,5) -> 4760 | I15: =+Lifestyle!BB25 -> 300718 | J15: =+J14 -> 0 | K15: =+Lifestyle!BD25 -> 3000 | L15: =+L14 -> 7000 | M15: =+M14 -> 103 | N15: =+N14 -> 60 | O15: =+O14 -> 85
A16: Ashley 24 | B16: =+CEILING(I16+J16+K16,10) -> 315050 | C16: =+L16 -> 7000 | D16: =+CEILING(Lifestyle!BH26*Shepparton!M16,5) -> 6505 | E16: =+CEILING(Lifestyle!BK26*Shepparton!N16,5) -> 4665 | F16: =SUM(B16:E16) -> 333220 | G16: =+CEILING(Lifestyle!BL26*Shepparton!O16,5) -> 5015 | I16: =+Lifestyle!BB26 -> 312046 | J16: =+J14 -> 0 | K16: =+Lifestyle!BD26 -> 3000 | L16: =+L14 -> 7000 | M16: =+M14 -> 103 | N16: =+N14 -> 60 | O16: =+O14 -> 85
A17: Ashley 25 | B17: =+CEILING(I17+J17+K17,10) -> 324090 | C17: =+L17 -> 7000 | D17: =+CEILING(Lifestyle!BH27*Shepparton!M17,5) -> 6950 | E17: =+CEILING(Lifestyle!BK27*Shepparton!N17,5) -> 4610 | F17: =SUM(B17:E17) -> 342650 | G17: =+CEILING(Lifestyle!BL27*Shepparton!O17,5) -> 5440 | I17: =+Lifestyle!BB27 -> 320081 | J17: =+J16 -> 0 | K17: =+Lifestyle!BD27 -> 4000 | L17: =+L16 -> 7000 | M17: =+M16 -> 103 | N17: =+N16 -> 60 | O17: =+O16 -> 85
A18: Ashley 25A | B18: =+CEILING(I18+J18+K18,10) -> 334230 | C18: =+L18 -> 7000 | D18: =+CEILING(Lifestyle!BH28*Shepparton!M18,5) -> 7040 | E18: =+CEILING(Lifestyle!BK28*Shepparton!N18,5) -> 4655 | F18: =SUM(B18:E18) -> 352925 | G18: =+CEILING(Lifestyle!BL28*Shepparton!O18,5) -> 5440 | I18: =+Lifestyle!BB28 -> 330229 | J18: =+J17 -> 0 | K18: =+Lifestyle!BD28 -> 4000 | L18: =+L17 -> 7000 | M18: =+M17 -> 103 | N18: =+N17 -> 60 | O18: =+O17 -> 85
A19: Ashley 26 | B19: =+CEILING(I19+J19+K19,10) -> 330980 | C19: =+L19 -> 7000 | D19: =+CEILING(Lifestyle!BH29*Shepparton!M19,5) -> 7050 | E19: =+CEILING(Lifestyle!BK29*Shepparton!N19,5) -> 4900 | F19: =SUM(B19:E19) -> 349930 | G19: =+CEILING(Lifestyle!BL29*Shepparton!O19,5) -> 5270 | I19: =+Lifestyle!BB29 -> 326973 | J19: =+J18 -> 0 | K19: =+Lifestyle!BD29 -> 4000 | L19: =+L18 -> 7000 | M19: =+M18 -> 103 | N19: =+N18 -> 60 | O19: =+O18 -> 85
A20: Ashley 27 | B20: =+CEILING(I20+J20+K20,10) -> 342910 | C20: =+L20 -> 7000 | D20: =+CEILING(Lifestyle!BH30*Shepparton!M20,5) -> 7995 | E20: =+CEILING(Lifestyle!BK30*Shepparton!N20,5) -> 6080 | F20: =SUM(B20:E20) -> 363985 | G20: =+CEILING(Lifestyle!BL30*Shepparton!O20,5) -> 5525 | I20: =+Lifestyle!BB30 -> 338903 | J20: =+J19 -> 0 | K20: =+Lifestyle!BD30 -> 4000 | L20: =+L19 -> 7000 | M20: =+M19 -> 103 | N20: =+N19 -> 60 | O20: =+O19 -> 85
A21: Ashley 28 | B21: =+CEILING(I21+J21+K21,10) -> 347740 | C21: =+L21 -> 7000 | D21: =+CEILING(Lifestyle!BH31*Shepparton!M21,5) -> 8895 | E21: =+CEILING(Lifestyle!BK31*Shepparton!N21,5) -> 4395 | F21: =SUM(B21:E21) -> 368030 | G21: =+CEILING(Lifestyle!BL31*Shepparton!O21,5) -> 5525 | I21: =+Lifestyle!BB31 -> 343732 | J21: =+J20 -> 0 | K21: =+Lifestyle!BD31 -> 4000 | L21: =+L20 -> 7000 | M21: =+M20 -> 103 | N21: =+N20 -> 60 | O21: =+O20 -> 85
A22: Ashley 28A | B22: =+CEILING(I22+J22+K22,10) -> 355250 | C22: =+L22 -> 7000 | D22: =+CEILING(Lifestyle!BH32*Shepparton!M22,5) -> 9335 | E22: =+CEILING(Lifestyle!BK32*Shepparton!N22,5) -> 5835 | F22: =SUM(B22:E22) -> 377420 | G22: =+CEILING(Lifestyle!BL32*Shepparton!O22,5) -> 5525 | I22: =+Lifestyle!BB32 -> 351250 | J22: =+J21 -> 0 | K22: =+Lifestyle!BD32 -> 4000 | L22: =+L21 -> 7000 | M22: =+M21 -> 103 | N22: =+N21 -> 60 | O22: =+O21 -> 85
A23: Ballina 24 | B23: =+CEILING(I23+J23+K23,10) -> 315600 | C23: =+L23 -> 7000 | D23: =+CEILING(Lifestyle!BH33*Shepparton!M23,5) -> 7970 | E23: =+CEILING(Lifestyle!BK33*Shepparton!N23,5) -> 3015 | F23: =SUM(B23:E23) -> 333585 | G23: =+CEILING(Lifestyle!BL33*Shepparton!O23,5) -> 4505 | I23: =+Lifestyle!BB33 -> 312597 | J23: =+J22 -> 0 | K23: =+Lifestyle!BD33 -> 3000 | L23: =+L22 -> 7000 | M23: =+M22 -> 103 | N23: =+N22 -> 60 | O23: =+O22 -> 85
A24: Ballina 30 | B24: =+CEILING(I24+J24+K24,10) -> 364750 | C24: =+L24 -> 7000 | D24: =+CEILING(Lifestyle!BH34*Shepparton!M24,5) -> 9640 | E24: =+CEILING(Lifestyle!BK34*Shepparton!N24,5) -> 5305 | F24: =SUM(B24:E24) -> 386695 | G24: =+CEILING(Lifestyle!BL34*Shepparton!O24,5) -> 5695 | I24: =+Lifestyle!BB34 -> 360743 | J24: =+J23 -> 0 | K24: =+Lifestyle!BD34 -> 4000 | L24: =+L23 -> 7000 | M24: =+M23 -> 103 | N24: =+N23 -> 60 | O24: =+O23 -> 85
A25: Ballina 30A | B25: =+CEILING(I25+J25+K25,10) -> 367040 | C25: =+L25 -> 7000 | D25: =+CEILING(Lifestyle!BH35*Shepparton!M25,5) -> 10765 | E25: =+CEILING(Lifestyle!BK35*Shepparton!N25,5) -> 5680 | F25: =SUM(B25:E25) -> 390485 | G25: =+CEILING(Lifestyle!BL35*Shepparton!O25,5) -> 5950 | I25: =+Lifestyle!BB35 -> 363040 | J25: =+J24 -> 0 | K25: =+Lifestyle!BD35 -> 4000 | L25: =+L24 -> 7000 | M25: =+M24 -> 103 | N25: =+N24 -> 60 | O25: =+O24 -> 85
A26: Ballina 33 | B26: =+CEILING(I26+J26+K26,10) -> 399090 | C26: =+L26 -> 7000 | D26: =+CEILING(Lifestyle!BH36*Shepparton!M26,5) -> 11835 | E26: =+CEILING(Lifestyle!BK36*Shepparton!N26,5) -> 5245 | F26: =SUM(B26:E26) -> 423170 | G26: =+CEILING(Lifestyle!BL36*Shepparton!O26,5) -> 6375 | I26: =+Lifestyle!BB36 -> 395086 | J26: =+J25 -> 0 | K26: =+Lifestyle!BD36 -> 4000 | L26: =+L25 -> 7000 | M26: =+M25 -> 103 | N26: =+N25 -> 60 | O26: =+O25 -> 85
A27: Ballina 39 | B27: =+CEILING(I27+J27+K27,10) -> 444180 | C27: =+L27 -> 7000 | D27: =+CEILING(Lifestyle!BH37*Shepparton!M27,5) -> 13260 | E27: =+CEILING(Lifestyle!BK37*Shepparton!N27,5) -> 7725 | F27: =SUM(B27:E27) -> 472165 | G27: =+CEILING(Lifestyle!BL37*Shepparton!O27,5) -> 6800 | I27: =+Lifestyle!BB37 -> 440177 | J27: =+J26 -> 0 | K27: =+Lifestyle!BD37 -> 4000 | L27: =+L26 -> 7000 | M27: =+M26 -> 103 | N27: =+N26 -> 60 | O27: =+O26 -> 85
A28: =+Lifestyle!A38 -> Bathurst 25 | B28: =+CEILING(I28+J28+K28,10) -> 347410 | C28: =+L28 -> 7000 | D28: =+CEILING(Lifestyle!BH38*Shepparton!M28,5) -> 7285 | E28: =+CEILING(Lifestyle!BK38*Shepparton!N28,5) -> 3960 | F28: =SUM(B28:E28) -> 365655 | G28: =+CEILING(Lifestyle!BL38*Shepparton!O28,5) -> 5185 | I28: =+Lifestyle!BB38 -> 343405 | J28: =+J27 -> 0 | K28: =+Lifestyle!BD38 -> 4000 | L28: =+L27 -> 7000 | M28: =+M27 -> 103 | N28: =+N27 -> 60 | O28: =+O27 -> 85
A29: =+Lifestyle!A39 -> Bathurst 30 | B29: =+CEILING(I29+J29+K29,10) -> 394390 | C29: =+L29 -> 7000 | D29: =+CEILING(Lifestyle!BH39*Shepparton!M29,5) -> 8780 | E29: =+CEILING(Lifestyle!BK39*Shepparton!N29,5) -> 5635 | F29: =SUM(B29:E29) -> 415805 | G29: =+CEILING(Lifestyle!BL39*Shepparton!O29,5) -> 5950 | I29: =+Lifestyle!BB39 -> 390384 | J29: =+J28 -> 0 | K29: =+Lifestyle!BD39 -> 4000 | L29: =+L28 -> 7000 | M29: =+M28 -> 103 | N29: =+N28 -> 60 | O29: =+O28 -> 85
A30: =+Lifestyle!A40 -> Bathurst 34 | B30: =+CEILING(I30+J30+K30,10) -> 415480 | C30: =+L30 -> 7000 | D30: =+CEILING(Lifestyle!BH40*Shepparton!M30,5) -> 9675 | E30: =+CEILING(Lifestyle!BK40*Shepparton!N30,5) -> 6350 | F30: =SUM(B30:E30) -> 438505 | G30: =+CEILING(Lifestyle!BL40*Shepparton!O30,5) -> 6290 | I30: =+Lifestyle!BB40 -> 411473 | J30: =+J29 -> 0 | K30: =+Lifestyle!BD40 -> 4000 | L30: =+L29 -> 7000 | M30: =+M29 -> 103 | N30: =+N29 -> 60 | O30: =+O29 -> 85
A31: Bayview 23 | B31: =+CEILING(I31+J31+K31,10) -> 316920 | C31: =+L31 -> 7000 | D31: =+CEILING(Lifestyle!BH41*Shepparton!M31,5) -> 8145 | E31: =+CEILING(Lifestyle!BK41*Shepparton!N31,5) -> 3005 | F31: =SUM(B31:E31) -> 335070 | G31: =+CEILING(Lifestyle!BL41*Shepparton!O31,5) -> 4760 | I31: =+Lifestyle!BB41 -> 313918 | J31: =+J30 -> 0 | K31: =+Lifestyle!BD41 -> 3000 | L31: =+L30 -> 7000 | M31: =+M30 -> 103 | N31: =+N30 -> 60 | O31: =+O30 -> 85
A32: Bayview 26 | B32: =+CEILING(I32+J32+K32,10) -> 339870 | C32: =+L32 -> 7000 | D32: =+CEILING(Lifestyle!BH42*Shepparton!M32,5) -> 7115 | E32: =+CEILING(Lifestyle!BK42*Shepparton!N32,5) -> 5060 | F32: =SUM(B32:E32) -> 359045 | G32: =+CEILING(Lifestyle!BL42*Shepparton!O32,5) -> 5270 | I32: =+Lifestyle!BB42 -> 335864 | J32: =+J31 -> 0 | K32: =+Lifestyle!BD42 -> 4000 | L32: =+L31 -> 7000 | M32: =+M31 -> 103 | N32: =+N31 -> 60 | O32: =+O31 -> 85
A33: Bayview 30 | B33: =+CEILING(I33+J33+K33,10) -> 375790 | C33: =+L33 -> 7000 | D33: =+CEILING(Lifestyle!BH43*Shepparton!M33,5) -> 8295 | E33: =+CEILING(Lifestyle!BK43*Shepparton!N33,5) -> 6975 | F33: =SUM(B33:E33) -> 398060 | G33: =+CEILING(Lifestyle!BL43*Shepparton!O33,5) -> 6120 | I33: =+Lifestyle!BB43 -> 371790 | J33: =+J32 -> 0 | K33: =+Lifestyle!BD43 -> 4000 | L33: =+L32 -> 7000 | M33: =+M32 -> 103 | N33: =+N32 -> 60 | O33: =+O32 -> 85
A34: Bondi 25 | B34: =+CEILING(I34+J34+K34,10) -> 330730 | C34: =+L34 -> 7000 | D34: =+CEILING(Lifestyle!BH44*Shepparton!M34,5) -> 9315 | E34: =+CEILING(Lifestyle!BK44*Shepparton!N34,5) -> 3765 | F34: =SUM(B34:E34) -> 350810 | G34: =+CEILING(Lifestyle!BL44*Shepparton!O34,5) -> 5355 | I34: =+Lifestyle!BB44 -> 326725 | J34: =+J33 -> 0 | K34: =+Lifestyle!BD44 -> 4000 | L34: =+L33 -> 7000 | M34: =+M33 -> 103 | N34: =+N33 -> 60 | O34: =+O33 -> 85
A35: Bondi 31 | B35: =+CEILING(I35+J35+K35,10) -> 369170 | C35: =+L35 -> 7000 | D35: =+CEILING(Lifestyle!BH45*Shepparton!M35,5) -> 10850 | E35: =+CEILING(Lifestyle!BK45*Shepparton!N35,5) -> 5070 | F35: =SUM(B35:E35) -> 392090 | G35: =+CEILING(Lifestyle!BL45*Shepparton!O35,5) -> 5780 | I35: =+Lifestyle!BB45 -> 365164 | J35: =+J34 -> 0 | K35: =+Lifestyle!BD45 -> 4000 | L35: =+L34 -> 7000 | M35: =+M34 -> 103 | N35: =+N34 -> 60 | O35: =+O34 -> 85
A36: Bondi 36 | B36: =+CEILING(I36+J36+K36,10) -> 399980 | C36: =+L36 -> 7000 | D36: =+CEILING(Lifestyle!BH46*Shepparton!M36,5) -> 12315 | E36: =+CEILING(Lifestyle!BK46*Shepparton!N36,5) -> 6445 | F36: =SUM(B36:E36) -> 425740 | G36: =+CEILING(Lifestyle!BL46*Shepparton!O36,5) -> 5865 | I36: =+Lifestyle!BB46 -> 395974 | J36: =+J35 -> 0 | K36: =+Lifestyle!BD46 -> 4000 | L36: =+L35 -> 7000 | M36: =+M35 -> 103 | N36: =+N35 -> 60 | O36: =+O35 -> 85
A37: Cambridge 22 | B37: =+CEILING(I37+J37+K37,10) -> 309750 | C37: =+L37 -> 7000 | D37: =+CEILING(Lifestyle!BH47*Shepparton!M37,5) -> 7965 | E37: =+CEILING(Lifestyle!BK47*Shepparton!N37,5) -> 3465 | F37: =SUM(B37:E37) -> 328180 | G37: =+CEILING(Lifestyle!BL47*Shepparton!O37,5) -> 4845 | I37: =+Lifestyle!BB47 -> 306745 | J37: =+J36 -> 0 | K37: =+Lifestyle!BD47 -> 3000 | L37: =+L36 -> 7000 | M37: =+M36 -> 103 | N37: =+N36 -> 60 | O37: =+O36 -> 85
A38: Cambridge 24 | B38: =+CEILING(I38+J38+K38,10) -> 329670 | C38: =+L38 -> 7000 | D38: =+CEILING(Lifestyle!BH48*Shepparton!M38,5) -> 7465 | E38: =+CEILING(Lifestyle!BK48*Shepparton!N38,5) -> 4845 | F38: =SUM(B38:E38) -> 348980 | G38: =+CEILING(Lifestyle!BL48*Shepparton!O38,5) -> 4845 | I38: =+Lifestyle!BB48 -> 326664 | J38: =+J37 -> 0 | K38: =+Lifestyle!BD48 -> 3000 | L38: =+L37 -> 7000 | M38: =+M37 -> 103 | N38: =+N37 -> 60 | O38: =+O37 -> 85
A39: Cambridge 26 | B39: =+CEILING(I39+J39+K39,10) -> 346130 | C39: =+L39 -> 7000 | D39: =+CEILING(Lifestyle!BH49*Shepparton!M39,5) -> 8805 | E39: =+CEILING(Lifestyle!BK49*Shepparton!N39,5) -> 5280 | F39: =SUM(B39:E39) -> 367215 | G39: =+CEILING(Lifestyle!BL49*Shepparton!O39,5) -> 5100 | I39: =+Lifestyle!BB49 -> 342124 | J39: =+J38 -> 0 | K39: =+Lifestyle!BD49 -> 4000 | L39: =+L38 -> 7000 | M39: =+M38 -> 103 | N39: =+N38 -> 60 | O39: =+O38 -> 85
A40: Cambridge 30 | B40: =+CEILING(I40+J40+K40,10) -> 376060 | C40: =+L40 -> 7000 | D40: =+CEILING(Lifestyle!BH50*Shepparton!M40,5) -> 8275 | E40: =+CEILING(Lifestyle!BK50*Shepparton!N40,5) -> 7495 | F40: =SUM(B40:E40) -> 398830 | G40: =+CEILING(Lifestyle!BL50*Shepparton!O40,5) -> 5525 | I40: =+Lifestyle!BB50 -> 372059 | J40: =+J39 -> 0 | K40: =+Lifestyle!BD50 -> 4000 | L40: =+L39 -> 7000 | M40: =+M39 -> 103 | N40: =+N39 -> 60 | O40: =+O39 -> 85
...

Sheet Investor
A1: INVESTOR PRICE LIST VALID UP TO AUGUST 2025
A2: HOUSE DESIGN | B2: BASE PRICE * | C2: 60sqm NATURAL CONCRETE | D2: ASPIRE FLOOR TILES | E2: ASPIRE CARPET | F2: ROLLER BLINDS TO ALL WINDOWS AND SLIDING DOORS | G2: TV ANTENNA | H2: SPLIT SYSTEM TO FAMILY ROOM | I2: WALL MOUNTED CLOTHESLINE | J2: COLORBOND LETTER BOX | K2: PACKAGE PRICE | O2: 60sqm natural concrete | P2: Aspire Tiles per sqm | Q2: Aspire Carpet per sqm
A3: Kiewa 15 | B3: =+CEILING(N3+M3,10) -> 242360 | C3: =+O3 -> 8400 | D3: =+CEILING(Lifestyle!BH139*Investor!P3,5) -> 3015 | E3: =+CEILING(Lifestyle!BK139*Investor!Q3,5) -> 2670 | F3: =9*195 -> 1755 | G3: =+Electrical!D17 -> 590 | H3: INCLUDED | I3: =+'Yard Items'!D33 -> 400 | J3: =+'Yard Items'!D29 -> 150 | K3: =SUM(B3:J3) -> 259340 | M3: 6000 | N3: =+Lifestyle!BB139 -> 236357 | O3: =60*140 -> 8400 | P3: 95 | Q3: 56
A4: Kiewa 17 | B4: =+CEILING(N4+M4,10) -> 260930 | C4: =+O4 -> 8400 | D4: =+CEILING(Lifestyle!BH140*Investor!P4,5) -> 3215 | E4: =+CEILING(Lifestyle!BK140*Investor!Q4,5) -> 3375 | F4: =10*195 -> 1950 | G4: =+G3 -> 590 | H4: INCLUDED | I4: =+I3 -> 400 | J4: =+J3 -> 150 | K4: =SUM(B4:J4) -> 279010 | M4: =+M3 -> 6000 | N4: =+Lifestyle!BB140 -> 254927 | O4: =+O3 -> 8400 | P4: =+P3 -> 95 | Q4: =+Q3 -> 56
A5: Kiewa 18 | B5: =+CEILING(N5+M5,10) -> 279100 | C5: =+O5 -> 8400 | D5: =+CEILING(Lifestyle!BH141*Investor!P5,5) -> 3935 | E5: =+CEILING(Lifestyle!BK141*Investor!Q5,5) -> 4255 | F5: =11*195 -> 2145 | G5: =+G4 -> 590 | H5: INCLUDED | I5: =+I4 -> 400 | J5: =+J4 -> 150 | K5: =SUM(B5:J5) -> 298975 | M5: =+M4 -> 6000 | N5: =+Lifestyle!BB141 -> 273100 | O5: =+O4 -> 8400 | P5: =+P4 -> 95 | Q5: =+Q4 -> 56
A6: Kiewa 21 | B6: =+CEILING(N6+M6,10) -> 288830 | C6: =+O6 -> 8400 | D6: =+CEILING(Lifestyle!BH142*Investor!P6,5) -> 4160 | E6: =+CEILING(Lifestyle!BK142*Investor!Q6,5) -> 4590 | F6: =12*195 -> 2340 | G6: =+G5 -> 590 | H6: 4150 | I6: =+I5 -> 400 | J6: =+J5 -> 150 | K6: =SUM(B6:J6) -> 313610 | M6: =+M5 -> 6000 | N6: =+Lifestyle!BB142 -> 282822 | O6: =+O5 -> 8400 | P6: =+P5 -> 95 | Q6: =+Q5 -> 56
A7: Prices based on a Standard Façade
A9: ## THESE RATES APPLY ONLY FOR INVESTORS, NOT OWNER-OCCUPIERS ##
A10: ## FOR OWNER-OCCUPIERS PLEASE USE THE MAIN PRICE LIST ##
A12: LANDSCAPING PRICES
A13: Size | C13: Seed | D13: Turf
A14: =+Landscaping!B14 -> 600m2 normal block | C14: =+Landscaping!C14 -> 24535 | D14: =+Landscaping!D14 -> 27985 | F14: Includes automated sprinkler sytem
A15: =+Landscaping!B15 -> 600m2 corner block | C15: =+Landscaping!C15 -> 27135 | D15: =+Landscaping!D15 -> 30585 | F15: Credit $600 to go down to a manual system
A16: =+Landscaping!B16 -> 800m2 normal block | C16: =+Landscaping!C16 -> 29385 | D16: =+Landscaping!D16 -> 34110
A17: =+Landscaping!B17 -> 800m2 corner block | C17: =+Landscaping!C17 -> 32010 | D17: =+Landscaping!D17 -> 36735

Sheet Echuca
A1: ECHUCA
A2: LIFESTYLE SINGLE STOREY PRICE LIST VALID UP TO AUG 2025
A3: HOUSE DESIGN | B3: BASE PRICE * | C3: 50sqm NATURAL CONCRETE | D3: LIFESTYLE FLOOR TILES | E3: LIFESTYLE CARPETS | F3: PACKAGE PRICE *50sqm NATURAL CONCRETE *CARPET *TILES | G3: PRICE TO ADD EAVES | I3: List price | J3: Promotional | K3: Bonus | L3: 50sqm natural concrete | M3: Tiles per sqm | N3: Carpet per sqm | O3: Eaves per lm
A4: Adelaide 18 | B4: =+CEILING(I4+J4+K4,10) -> 295550 | C4: =+L4 -> 7000 | D4: =+Shepparton!D4 -> 5010 | E4: =+Shepparton!E4 -> 2785 | F4: =SUM(B4:E4) -> 310345 | G4: =+Shepparton!G4 -> 4420 | I4: =+Lifestyle!BC14 -> 292541 | J4: =+Lifestyle!BB7 -> 0 | K4: =+Lifestyle!BD14 -> 3000 | L4: =50*'2.TRAVEL'!H13 -> 7000 | M4: 103 | N4: 60 | O4: 65
A5: Adelaide 21 | B5: =+CEILING(I5+J5+K5,10) -> 309980 | C5: =+L5 -> 7000 | D5: =+Shepparton!D5 -> 5140 | E5: =+Shepparton!E5 -> 4100 | F5: =SUM(B5:E5) -> 326220 | G5: =+Shepparton!G5 -> 4845 | I5: =+Lifestyle!BC15 -> 306971 | J5: =+J4 -> 0 | K5: =+Lifestyle!BD15 -> 3000 | L5: =+L4 -> 7000 | M5: =+M4 -> 103 | N5: =+N4 -> 60 | O5: =+O4 -> 65
A6: Adelaide 22A | B6: =+CEILING(I6+J6+K6,10) -> 324000 | C6: =+L6 -> 7000 | D6: =+Shepparton!D6 -> 5935 | E6: =+Shepparton!E6 -> 4085 | F6: =SUM(B6:E6) -> 341020 | G6: =+Shepparton!G6 -> 5100 | I6: =+Lifestyle!BC16 -> 320996 | J6: =+J5 -> 0 | K6: =+Lifestyle!BD16 -> 3000 | L6: =+L5 -> 7000 | M6: =+M5 -> 103 | N6: =+N5 -> 60 | O6: =+O5 -> 65
A7: Adelaide 22B | B7: =+CEILING(I7+J7+K7,10) -> 325640 | C7: =+L7 -> 7000 | D7: =+Shepparton!D7 -> 5885 | E7: =+Shepparton!E7 -> 3985 | F7: =SUM(B7:E7) -> 342510 | G7: =+Shepparton!G7 -> 5100 | I7: =+Lifestyle!BC17 -> 322640 | J7: =+J6 -> 0 | K7: =+Lifestyle!BD17 -> 3000 | L7: =+L6 -> 7000 | M7: =+M6 -> 103 | N7: =+N6 -> 60 | O7: =+O6 -> 65
A8: Adelaide 24 | B8: =+CEILING(I8+J8+K8,10) -> 333230 | C8: =+L8 -> 7000 | D8: =+Shepparton!D8 -> 6420 | E8: =+Shepparton!E8 -> 4990 | F8: =SUM(B8:E8) -> 351640 | G8: =+Shepparton!G8 -> 5270 | I8: =+Lifestyle!BC18 -> 330230 | J8: =+J7 -> 0 | K8: =+Lifestyle!BD18 -> 3000 | L8: =+L7 -> 7000 | M8: =+M7 -> 103 | N8: =+N7 -> 60 | O8: =+O7 -> 65
A9: Ashfield 24 | B9: =+CEILING(I9+J9+K9,10) -> 335580 | C9: =+L9 -> 7000 | D9: =+Shepparton!D9 -> 8670 | E9: =+Shepparton!E9 -> 3475 | F9: =SUM(B9:E9) -> 354725 | G9: =+Shepparton!G9 -> 4930 | I9: =+Lifestyle!BC19 -> 332578 | J9: =+J8 -> 0 | K9: =+Lifestyle!BD19 -> 3000 | L9: =+L8 -> 7000 | M9: =+M8 -> 103 | N9: =+N8 -> 60 | O9: =+O8 -> 65
A10: Ashfield 30 | B10: =+CEILING(I10+J10+K10,10) -> 372840 | C10: =+L10 -> 7000 | D10: =+Shepparton!D10 -> 7940 | E10: =+Shepparton!E10 -> 5610 | F10: =SUM(B10:E10) -> 393390 | G10: =+Shepparton!G10 -> 5100 | I10: =+Lifestyle!BC20 -> 368840 | J10: =+J9 -> 0 | K10: =+Lifestyle!BD20 -> 4000 | L10: =+L9 -> 7000 | M10: =+M9 -> 103 | N10: =+N9 -> 60 | O10: =+O9 -> 65
A11: Ashfield 34 | B11: =+CEILING(I11+J11+K11,10) -> 399470 | C11: =+L11 -> 7000 | D11: =+Shepparton!D11 -> 8440 | E11: =+Shepparton!E11 -> 6700 | F11: =SUM(B11:E11) -> 421610 | G11: =+Shepparton!G11 -> 6290 | I11: =+Lifestyle!BC21 -> 395470 | J11: =+J10 -> 0 | K11: =+Lifestyle!BD21 -> 4000 | L11: =+L10 -> 7000 | M11: =+M10 -> 103 | N11: =+N10 -> 60 | O11: =+O10 -> 65
A12: Ashley 19 | B12: =+CEILING(I12+J12+K12,10) -> 293860 | C12: =+L12 -> 7000 | D12: =+Shepparton!D12 -> 5805 | E12: =+Shepparton!E12 -> 2805 | F12: =SUM(B12:E12) -> 309470 | G12: =+Shepparton!G12 -> 4335 | I12: =+Lifestyle!BC22 -> 290856 | J12: =+J11 -> 0 | K12: =+Lifestyle!BD22 -> 3000 | L12: =+L11 -> 7000 | M12: =+M11 -> 103 | N12: =+N11 -> 60 | O12: =+O11 -> 65
A13: Ashley 21 | B13: =+CEILING(I13+J13+K13,10) -> 312930 | C13: =+L13 -> 7000 | D13: =+Shepparton!D13 -> 6975 | E13: =+Shepparton!E13 -> 3735 | F13: =SUM(B13:E13) -> 330640 | G13: =+Shepparton!G13 -> 5015 | I13: =+Lifestyle!BC23 -> 309921 | J13: =+J12 -> 0 | K13: =+Lifestyle!BD23 -> 3000 | L13: =+L12 -> 7000 | M13: =+M12 -> 103 | N13: =+N12 -> 60 | O13: =+O12 -> 65
A14: Ashley 22 | B14: =+CEILING(I14+J14+K14,10) -> 310550 | C14: =+L14 -> 7000 | D14: =+Shepparton!D14 -> 6855 | E14: =+Shepparton!E14 -> 3875 | F14: =SUM(B14:E14) -> 328280 | G14: =+Shepparton!G14 -> 4760 | I14: =+Lifestyle!BC24 -> 307545 | J14: =+J12 -> 0 | K14: =+Lifestyle!BD24 -> 3000 | L14: =+L12 -> 7000 | M14: =+M12 -> 103 | N14: =+N12 -> 60 | O14: =+O12 -> 65
A15: Ashley 22A | B15: =+CEILING(I15+J15+K15,10) -> 316920 | C15: =+L15 -> 7000 | D15: =+Shepparton!D15 -> 7470 | E15: =+Shepparton!E15 -> 3615 | F15: =SUM(B15:E15) -> 335005 | G15: =+Shepparton!G15 -> 4760 | I15: =+Lifestyle!BC25 -> 313916 | J15: =+J13 -> 0 | K15: =+Lifestyle!BD25 -> 3000 | L15: =+L13 -> 7000 | M15: =+M13 -> 103 | N15: =+N13 -> 60 | O15: =+O13 -> 65
A16: Ashley 24 | B16: =+CEILING(I16+J16+K16,10) -> 328570 | C16: =+L16 -> 7000 | D16: =+Shepparton!D16 -> 6505 | E16: =+Shepparton!E16 -> 4665 | F16: =SUM(B16:E16) -> 346740 | G16: =+Shepparton!G16 -> 5015 | I16: =+Lifestyle!BC26 -> 325561 | J16: =+J14 -> 0 | K16: =+Lifestyle!BD26 -> 3000 | L16: =+L14 -> 7000 | M16: =+M14 -> 103 | N16: =+N14 -> 60 | O16: =+O14 -> 65
A17: Ashley 25 | B17: =+CEILING(I17+J17+K17,10) -> 337410 | C17: =+L17 -> 7000 | D17: =+Shepparton!D17 -> 6950 | E17: =+Shepparton!E17 -> 4610 | F17: =SUM(B17:E17) -> 355970 | G17: =+Shepparton!G17 -> 5440 | I17: =+Lifestyle!BC27 -> 333403 | J17: =+J16 -> 0 | K17: =+Lifestyle!BD27 -> 4000 | L17: =+L16 -> 7000 | M17: =+M16 -> 103 | N17: =+N16 -> 60 | O17: =+O16 -> 65
A18: Ashley 25A | B18: =+CEILING(I18+J18+K18,10) -> 347550 | C18: =+L18 -> 7000 | D18: =+Shepparton!D18 -> 7040 | E18: =+Shepparton!E18 -> 4655 | F18: =SUM(B18:E18) -> 366245 | G18: =+Shepparton!G18 -> 5440 | I18: =+Lifestyle!BC28 -> 343545 | J18: =+J17 -> 0 | K18: =+Lifestyle!BD28 -> 4000 | L18: =+L17 -> 7000 | M18: =+M17 -> 103 | N18: =+N17 -> 60 | O18: =+O17 -> 65
A19: Ashley 26 | B19: =+CEILING(I19+J19+K19,10) -> 344210 | C19: =+L19 -> 7000 | D19: =+Shepparton!D19 -> 7050 | E19: =+Shepparton!E19 -> 4900 | F19: =SUM(B19:E19) -> 363160 | G19: =+Shepparton!G19 -> 5270 | I19: =+Lifestyle!BC29 -> 340209 | J19: =+J18 -> 0 | K19: =+Lifestyle!BD29 -> 4000 | L19: =+L18 -> 7000 | M19: =+M18 -> 103 | N19: =+N18 -> 60 | O19: =+O18 -> 65
A20: Ashley 27 | B20: =+CEILING(I20+J20+K20,10) -> 356220 | C20: =+L20 -> 7000 | D20: =+Shepparton!D20 -> 7995 | E20: =+Shepparton!E20 -> 6080 | F20: =SUM(B20:E20) -> 377295 | G20: =+Shepparton!G20 -> 5525 | I20: =+Lifestyle!BC30 -> 352214 | J20: =+J19 -> 0 | K20: =+Lifestyle!BD30 -> 4000 | L20: =+L19 -> 7000 | M20: =+M19 -> 103 | N20: =+N19 -> 60 | O20: =+O19 -> 65
A21: Ashley 28 | B21: =+CEILING(I21+J21+K21,10) -> 360760 | C21: =+L21 -> 7000 | D21: =+Shepparton!D21 -> 8895 | E21: =+Shepparton!E21 -> 4395 | F21: =SUM(B21:E21) -> 381050 | G21: =+Shepparton!G21 -> 5525 | I21: =+Lifestyle!BC31 -> 356760 | J21: =+J20 -> 0 | K21: =+Lifestyle!BD31 -> 4000 | L21: =+L20 -> 7000 | M21: =+M20 -> 103 | N21: =+N20 -> 60 | O21: =+O20 -> 65
A22: Ashley 28A | B22: =+CEILING(I22+J22+K22,10) -> 368510 | C22: =+L22 -> 7000 | D22: =+Shepparton!D22 -> 9335 | E22: =+Shepparton!E22 -> 5835 | F22: =SUM(B22:E22) -> 390680 | G22: =+Shepparton!G22 -> 5525 | I22: =+Lifestyle!BC32 -> 364509 | J22: =+J21 -> 0 | K22: =+Lifestyle!BD32 -> 4000 | L22: =+L21 -> 7000 | M22: =+M21 -> 103 | N22: =+N21 -> 60 | O22: =+O21 -> 65
A23: Ballina 24 | B23: =+CEILING(I23+J23+K23,10) -> 328840 | C23: =+L23 -> 7000 | D23: =+Shepparton!D23 -> 7970 | E23: =+Shepparton!E23 -> 3015 | F23: =SUM(B23:E23) -> 346825 | G23: =+Shepparton!G23 -> 4505 | I23: =+Lifestyle!BC33 -> 325831 | J23: =+J22 -> 0 | K23: =+Lifestyle!BD33 -> 3000 | L23: =+L22 -> 7000 | M23: =+M22 -> 103 | N23: =+N22 -> 60 | O23: =+O22 -> 65
A24: Ballina 30 | B24: =+CEILING(I24+J24+K24,10) -> 377980 | C24: =+L24 -> 7000 | D24: =+Shepparton!D24 -> 9640 | E24: =+Shepparton!E24 -> 5305 | F24: =SUM(B24:E24) -> 399925 | G24: =+Shepparton!G24 -> 5695 | I24: =+Lifestyle!BC34 -> 373971 | J24: =+J23 -> 0 | K24: =+Lifestyle!BD34 -> 4000 | L24: =+L23 -> 7000 | M24: =+M23 -> 103 | N24: =+N23 -> 60 | O24: =+O23 -> 65
A25: Ballina 30A | B25: =+CEILING(I25+J25+K25,10) -> 380300 | C25: =+L25 -> 7000 | D25: =+Shepparton!D25 -> 10765 | E25: =+Shepparton!E25 -> 5680 | F25: =SUM(B25:E25) -> 403745 | G25: =+Shepparton!G25 -> 5950 | I25: =+Lifestyle!BC35 -> 376292 | J25: =+J24 -> 0 | K25: =+Lifestyle!BD35 -> 4000 | L25: =+L24 -> 7000 | M25: =+M24 -> 103 | N25: =+N24 -> 60 | O25: =+O24 -> 65
A26: Ballina 33 | B26: =+CEILING(I26+J26+K26,10) -> 412310 | C26: =+L26 -> 7000 | D26: =+Shepparton!D26 -> 11835 | E26: =+Shepparton!E26 -> 5245 | F26: =SUM(B26:E26) -> 436390 | G26: =+Shepparton!G26 -> 6375 | I26: =+Lifestyle!BC36 -> 408310 | J26: =+J24 -> 0 | K26: =+Lifestyle!BD36 -> 4000 | L26: =+L24 -> 7000 | M26: =+M24 -> 103 | N26: =+N24 -> 60 | O26: =+O24 -> 65
A27: Ballina 39 | B27: =+CEILING(I27+J27+K27,10) -> 457350 | C27: =+L27 -> 7000 | D27: =+Shepparton!D27 -> 13260 | E27: =+Shepparton!E27 -> 7725 | F27: =SUM(B27:E27) -> 485335 | G27: =+Shepparton!G27 -> 6800 | I27: =+Lifestyle!BC37 -> 453342 | J27: =+J26 -> 0 | K27: =+Lifestyle!BD37 -> 4000 | L27: =+L26 -> 7000 | M27: =+M26 -> 103 | N27: =+N26 -> 60 | O27: =+O26 -> 65
A28: =+Lifestyle!A38 -> Bathurst 25 | B28: =+CEILING(I28+J28+K28,10) -> 360680 | C28: =+L28 -> 7000 | D28: =+Shepparton!D28 -> 7285 | E28: =+Shepparton!E28 -> 3960 | F28: =SUM(B28:E28) -> 378925 | G28: =+Shepparton!G28 -> 5185 | I28: =+Lifestyle!BC38 -> 356677 | J28: =+J27 -> 0 | K28: =+Lifestyle!BD38 -> 4000 | L28: =+L27 -> 7000 | M28: =+M27 -> 103 | N28: =+N27 -> 60 | O28: =+O27 -> 65
A29: =+Lifestyle!A39 -> Bathurst 30 | B29: =+CEILING(I29+J29+K29,10) -> 407720 | C29: =+L29 -> 7000 | D29: =+Shepparton!D29 -> 8780 | E29: =+Shepparton!E29 -> 5635 | F29: =SUM(B29:E29) -> 429135 | G29: =+Shepparton!G29 -> 5950 | I29: =+Lifestyle!BC39 -> 403713 | J29: =+J28 -> 0 | K29: =+Lifestyle!BD39 -> 4000 | L29: =+L28 -> 7000 | M29: =+M28 -> 103 | N29: =+N28 -> 60 | O29: =+O28 -> 65
A30: =+Lifestyle!A40 -> Bathurst 34 | B30: =+CEILING(I30+J30+K30,10) -> 426050 | C30: =+L30 -> 7000 | D30: =+Shepparton!D30 -> 9675 | E30: =+Shepparton!E30 -> 6350 | F30: =SUM(B30:E30) -> 449075 | G30: =+Shepparton!G30 -> 6290 | I30: =+Lifestyle!BC40 -> 422047 | J30: =+J29 -> 0 | K30: =+Lifestyle!BD40 -> 4000 | L30: =+L29 -> 7000 | M30: =+M29 -> 103 | N30: =+N29 -> 60 | O30: =+O29 -> 65
A31: Bayview 23 | B31: =+CEILING(I31+J31+K31,10) -> 330140 | C31: =+L31 -> 7000 | D31: =+Shepparton!D31 -> 8145 | E31: =+Shepparton!E31 -> 3005 | F31: =SUM(B31:E31) -> 348290 | G31: =+Shepparton!G31 -> 4760 | I31: =+Lifestyle!BC41 -> 327135 | J31: =+J30 -> 0 | K31: =+Lifestyle!BD41 -> 3000 | L31: =+L30 -> 7000 | M31: =+M30 -> 103 | N31: =+N30 -> 60 | O31: =+O30 -> 65
A32: Bayview 26 | B32: =+CEILING(I32+J32+K32,10) -> 353100 | C32: =+L32 -> 7000 | D32: =+Shepparton!D32 -> 7115 | E32: =+Shepparton!E32 -> 5060 | F32: =SUM(B32:E32) -> 372275 | G32: =+Shepparton!G32 -> 5270 | I32: =+Lifestyle!BC42 -> 349100 | J32: =+J31 -> 0 | K32: =+Lifestyle!BD42 -> 4000 | L32: =+L31 -> 7000 | M32: =+M31 -> 103 | N32: =+N31 -> 60 | O32: =+O31 -> 65
A33: Bayview 30 | B33: =+CEILING(I33+J33+K33,10) -> 390550 | C33: =+L33 -> 7000 | D33: =+Shepparton!D33 -> 8295 | E33: =+Shepparton!E33 -> 6975 | F33: =SUM(B33:E33) -> 412820 | G33: =+Shepparton!G33 -> 6120 | I33: =+Lifestyle!BC43 -> 386547 | J33: =+J32 -> 0 | K33: =+Lifestyle!BD43 -> 4000 | L33: =+L32 -> 7000 | M33: =+M32 -> 103 | N33: =+N32 -> 60 | O33: =+O32 -> 65
A34: Bondi 25 | B34: =+CEILING(I34+J34+K34,10) -> 343960 | C34: =+L34 -> 7000 | D34: =+Shepparton!D34 -> 9315 | E34: =+Shepparton!E34 -> 3765 | F34: =SUM(B34:E34) -> 364040 | G34: =+Shepparton!G34 -> 5355 | I34: =+Lifestyle!BC44 -> 339954 | J34: =+J33 -> 0 | K34: =+Lifestyle!BD44 -> 4000 | L34: =+L33 -> 7000 | M34: =+M33 -> 103 | N34: =+N33 -> 60 | O34: =+O33 -> 65
A35: Bondi 31 | B35: =+CEILING(I35+J35+K35,10) -> 383710 | C35: =+L35 -> 7000 | D35: =+Shepparton!D35 -> 10850 | E35: =+Shepparton!E35 -> 5070 | F35: =SUM(B35:E35) -> 406630 | G35: =+Shepparton!G35 -> 5780 | I35: =+Lifestyle!BC45 -> 379707 | J35: =+J34 -> 0 | K35: =+Lifestyle!BD45 -> 4000 | L35: =+L34 -> 7000 | M35: =+M34 -> 103 | N35: =+N34 -> 60 | O35: =+O34 -> 65
A36: Bondi 36 | B36: =+CEILING(I36+J36+K36,10) -> 413150 | C36: =+L36 -> 7000 | D36: =+Shepparton!D36 -> 12315 | E36: =+Shepparton!E36 -> 6445 | F36: =SUM(B36:E36) -> 438910 | G36: =+Shepparton!G36 -> 5865 | I36: =+Lifestyle!BC46 -> 409146 | J36: =+J35 -> 0 | K36: =+Lifestyle!BD46 -> 4000 | L36: =+L35 -> 7000 | M36: =+M35 -> 103 | N36: =+N35 -> 60 | O36: =+O35 -> 65
A37: Cambridge 22 | B37: =+CEILING(I37+J37+K37,10) -> 322820 | C37: =+L37 -> 7000 | D37: =+Shepparton!D37 -> 7965 | E37: =+Shepparton!E37 -> 3465 | F37: =SUM(B37:E37) -> 341250 | G37: =+Shepparton!G37 -> 4845 | I37: =+Lifestyle!BC47 -> 319820 | J37: =+J36 -> 0 | K37: =+Lifestyle!BD47 -> 3000 | L37: =+L36 -> 7000 | M37: =+M36 -> 103 | N37: =+N36 -> 60 | O37: =+O36 -> 65
A38: Cambridge 24 | B38: =+CEILING(I38+J38+K38,10) -> 342820 | C38: =+L38 -> 7000 | D38: =+Shepparton!D38 -> 7465 | E38: =+Shepparton!E38 -> 4845 | F38: =SUM(B38:E38) -> 362130 | G38: =+Shepparton!G38 -> 4845 | I38: =+Lifestyle!BC48 -> 339818 | J38: =+J37 -> 0 | K38: =+Lifestyle!BD48 -> 3000 | L38: =+L37 -> 7000 | M38: =+M37 -> 103 | N38: =+N37 -> 60 | O38: =+O37 -> 65
A39: Cambridge 26 | B39: =+CEILING(I39+J39+K39,10) -> 359290 | C39: =+L39 -> 7000 | D39: =+Shepparton!D39 -> 8805 | E39: =+Shepparton!E39 -> 5280 | F39: =SUM(B39:E39) -> 380375 | G39: =+Shepparton!G39 -> 5100 | I39: =+Lifestyle!BC49 -> 355281 | J39: =+J38 -> 0 | K39: =+Lifestyle!BD49 -> 4000 | L39: =+L38 -> 7000 | M39: =+M38 -> 103 | N39: =+N38 -> 60 | O39: =+O38 -> 65
A40: Cambridge 30 | B40: =+CEILING(I40+J40+K40,10) -> 389270 | C40: =+L40 -> 7000 | D40: =+Shepparton!D40 -> 8275 | E40: =+Shepparton!E40 -> 7495 | F40: =SUM(B40:E40) -> 412040 | G40: =+Shepparton!G40 -> 5525 | I40: =+Lifestyle!BC50 -> 385270 | J40: =+J39 -> 0 | K40: =+Lifestyle!BD50 -> 4000 | L40: =+L39 -> 7000 | M40: =+M39 -> 103 | N40: =+N39 -> 60 | O40: =+O39 -> 65
...

Sheet Value Packs
B2: LIFESTYLE VALUE PACKS - NOV 2024
B4: ENTRANCE PACK
B5: 1200mm x 2040mm timber glass front door | C5: 1340
B6: Nexion Trilock handle | C6: 175
B7: Total | C7: =SUM(C5:C6) -> 1515
B9: KITCHEN CABINETRY PACK
B10: 2 Banks of drawers | C10: 660
B11: Twin bin in drawer with drawer below | C11: 250
B12: Fridge overhead cupboard | C12: 960 | E12: 1000mm with one side panel
B13: Total | C13: =SUM(C10:C12) -> 1870
B15: KITCHEN APPLIANCE PACK
B16: 90cm Inbuilt oven & gas cooktop | C16: 1355
B17: 70cm Intergrated rangehood | C17: 165
B18: Water point to fridge | C18: 200
B19: Total | C19: =SUM(C16:C18) -> 1720
B21: KITCHEN BENCHTOP PACK
B22: 20mm Stone benchtop | C22: 3625 | E22: (3.2m wall bench & 2.7m island)
B23: Undermount sink | C23: 355
B24: Total | C24: =SUM(C22:C23) -> 3980
B26: BATHROOM/ENSUITE INDULGENT PACK
B27: 20mm Stone vanity benchtops | C27: 1350 | E27: (up to 1 x 1800mm & 1 x 900mm)
B28: Above counter basins with tower mixers | C28: 450 | E28: x3
B29: Tiled recess shelf to showers | C29: 800
B30: Dual shower head to ensuite | C30: 250
B31: Total | C31: =SUM(C27:C30) -> 2850
B33: LAUNDRY INDULGENT PACK
B34: Extend bench & cabinets up to 2m | C34: 2800
B35: Pull out clothesbasket | C35: 220
B36: Total | C36: =SUM(C34:C35) -> 3020
B38: LIGHTING PACK 1
B39: 30 X LED downlights | C39: 2550 | E39: replaces 15 light points
B40: Total | C40: =SUM(C39:C39) -> 2550
B42: LIGHTING PACK 2
B43: 30 X LED downlights | C43: 2550 | E43: replaces 15 light points
B44: 3 X Pendant lights above island bench | C44: 1155 | E44: 220 per pendant
B45: Total | C45: =SUM(C43:C44) -> 3705
B47: LIGHTING PACK 3
B48: 30 X LED downlights | C48: 2550 | E48: replaces 15 light points
B49: 3 X Pendant lights above island bench | C49: =+C44 -> 1155 | E49: 220 per pendant
B50: 3 X Wall mounted feature lights to the front façade with motion sensor | C50: 1290
...

Sheet Sandown 32 Display
B4: ABN: 50 105 889 745
B5: 7961 Goulburn Valley Hwy | E5: Telephone 5823 1859
B6: P O BOX 922 | E6: Display Home 5832 6082
B7: SHEPPARTON VIC 3632 | E7: DB-U 9856
B9: Dear | C9: =+C48 -> 0
B11: RE: PRELIMINARY PRICING
B13: Thank you for your interest in building a new home with Cavalier Homes Goulburn Valley, we greatly
B14: appreciate the opportunity to work with you designing and building your new home.
B16: Please find attached the preliminary pricing to build a house on your land at
B17: =+C52 -> 0
B19: This preliminary pricing is provided as a guide and is subject to review after 30 days or before this
B20: time if a new price list is released in the interim.
B22: If you are pleased with the preliminary price, we can then provide a firm price once you have paid an
B23: initial preliminary service fee of $2,000 - (this will secure the price as per the terms and conditions
B24: of the Cavalier Homes Goulburn Valley Ground Work document which we will discuss further should
B25: you wish to proceed to the next stage).
B27: Once the initial preliminary service fee is received, we will arrange to have working drawings drafted
B28: which will show you fully detailed plan of the interior and exterior of your home.
B29: We will also engage an independent, qualified engineer to provide a slab design based on your home
B30: design and the results of the soil test inspection carried out on your block.
B32: As discussed, we will provide you with a final fixed price once the following are completed:
B33: The colour selections
... B55: PRE- CONSTRUCTION
B56: Soil test and site inspection of your block | D56: Included
B57: Independent qualified engineer designed slab | D57: Included
B58: Rescode investigation | D58: Included
B59: Building permit and associated fees (does not include planning permit) | D59: Included
B60: Development application for NSW jobs | D60: Included
B61: Builder's insurances | D61: Included
B62: Independent 6 star energy rating | D62: Included
B63: SERVICE CONNECTIONS
B64: Sewer run and connection fees to 700m2 block | D64: Included
B65: Water run and connection fees to 6m front setback | D65: Included
B66: Stormwater connection to 6m front setback | D66: Included
B67: Electricity run to 6m front setback (does not include connection fee) | D67: Included
B68: Gas service is to be supplied by the retailer
B69: FOUNDATIONS
B70: Site fall up to 200mm | D70: Included
B71: MD class concrete slab (floor height at least 250mm - there is no allowance for piers) | D71: Included
B72: Concrete pump | D72: Included
...

Sheet Travel Working
A1: Draftee travel per km | B1: =+((65+65)/100) -> 1.3
A2: Truck cost per km | B2: 1.65 | F2: 16/10/24 - Add $50 for TV Antenna Instal
A3: Carpenter travel per km | B3: 1.65
A4: Supervisor tavel per km | B4: 1.65
A5: Concrete pump travel | B5: 4
A6: Stone benchtops | B6: 6
B7: Kms | C7: Cost per km return | D7: Bunnings delivery | E7: Drafting inspwction travel | F7: Temp fencing travel | G7: Skip run | H7: site screpe travel | I7: Crusher dust | K7: Concrete supply | M7: Pump travel | P7: Bricks delivery | R7: Brick sand | T7: Stone travel | W7: Supervisor travel
A8: SHEPPARTON | B8: 20 | C8: =+B2*2 -> 3.3 | D8: 45.45 | E8: =+C8*B8 -> 66 | F8: =+C8*B8 -> 66 | G8: =+C8*B8*6 -> 396 | H8: =+C8*B8 -> 66 | I8: 51 | J8: =+I8*35 -> 1785 | K8: 210 | L8: =+K8*60 -> 12600 | M8: =+B5 -> 4 | N8: =+B8-80 -> -60 | O8: =IF((N8>0),(N8*M8*2),) -> 0 | P8: 55 | Q8: =+P8*8 -> 440 | R8: 44 | S8: =+R8*9 -> 396 | T8: =+B6 -> 6 | V8: =+B4 -> 1.65 | W8: =+V8*2*B8*10 -> 660 | AF8: =+A8 -> SHEPPARTON
A9: ALEXANDRA | B9: 120 | C9: =+C8 -> 3.3 | D9: 150 | E9: =+C9*B9 -> 396 | F9: =+C9*B9 -> 396 | G9: =+C9*B9*6 -> 2376 | H9: =+C9*B9 -> 396 | I9: 85 | J9: =+I9*35 -> 2975 | K9: 287 | L9: =+K9*60 -> 17220 | M9: =+M8 -> 4 | N9: =+B9-80 -> 40 | O9: =IF((N9>0),(N9*M9*2),) -> 320 | P9: 65 | Q9: =+P9*8 -> 520 | R9: 80 | S9: =+R9*9 -> 720 | T9: =+T8 -> 6 | U9: =+IF(((B9-80)>0),((B9-80)*T9),0) -> 240 | V9: =+V8 -> 1.65 | W9: =+V9*2*B9*10 -> 3960 | AF9: =+A9 -> ALEXANDRA | AG9: =+C94-B94 -> 29794.75 | AH9: =+CEILING(AG9*1.36,10) -> 40530
A10: AVENEL | B10: 71 | C10: =+C9 -> 3.3 | D10: 110 | E10: =+C10*B10 -> 234.3 | F10: =+C10*B10 -> 234.3 | G10: =+C10*B10*6 -> 1405.8 | H10: =+C10*B10 -> 234.3 | I10: 65 | J10: =+I10*35 -> 2275 | K10: 210 | L10: =+K10*60 -> 12600 | M10: =+M9 -> 4 | N10: =+B10-80 -> -9 | O10: =IF((N10>0),(N10*M10*2),) -> 0 | P10: 55 | Q10: =+P10*8 -> 440 | R10: 56 | S10: =+R10*9 -> 504 | T10: =+T9 -> 6 | U10: =+IF(((B10-80)>0),((B10-80)*T10),0) -> 0 | V10: =+V9 -> 1.65 | W10: =+V10*2*B10*10 -> 2343 | AF10: =+A10 -> AVENEL | AG10: =+D94-B94 -> 10821.05 | AH10: =+CEILING(AG10*1.36,10) -> 14720
A11: BENALLA | B11: 62 | C11: =+C10 -> 3.3 | D11: 70 | E11: =+C11*B11 -> 204.6 | F11: =+C11*B11 -> 204.6 | G11: =+C11*B11*6 -> 1227.6 | H11: =+C11*B11 -> 204.6 | I11: 65 | J11: =+I11*35 -> 2275 | K11: 235 | L11: =+K11*60 -> 14100 | M11: =+M10 -> 4 | N11: =+B11-80 -> -18 | O11: =IF((N11>0),(N11*M11*2),) -> 0 | P11: 55 | Q11: =+P11*8 -> 440 | R11: 54 | S11: =+R11*9 -> 486 | T11: =+T10 -> 6 | U11: =+IF(((B11-80)>0),((B11-80)*T11),0) -> 0 | V11: =+V10 -> 1.65 | W11: =+V11*2*B11*10 -> 2046 | AF11: =+A11 -> BENALLA | AG11: =+E94-B94 -> 10219.35 | AH11: =+CEILING(AG11*1.36,10) -> 13900
A12: COBRAM | B12: 71 | C12: =+C11 -> 3.3 | D12: 70 | E12: =+C12*B12 -> 234.3 | F12: =+C12*B12 -> 234.3 | G12: =+C12*B12*6 -> 1405.8 | H12: =+C12*B12 -> 234.3 | I12: 65 | J12: =+I12*35 -> 2275 | K12: 220 | L12: =+K12*60 -> 13200 | M12: =+M11 -> 4 | N12: =+B12-80 -> -9 | O12: =IF((N12>0),(N12*M12*2),) -> 0 | P12: 70 | Q12: =+P12*8 -> 560 | R12: 54 | S12: =+R12*9 -> 486 | T12: =+T11 -> 6 | U12: =+IF(((B12-80)>0),((B12-80)*T12),0) -> 0 | V12: =+V11 -> 1.65 | W12: =+V12*2*B12*10 -> 2343 | AF12: =+A12 -> COBRAM | AG12: =+F94-B94 -> 10123.05 | AH12: =+CEILING(AG12*1.36,10) -> 13770
