Workbook

Sheet Fast Key
A1: Standard Rates
A3: 50sqm Concrete paving | BB3: =50*140 -> 7000 | BD3: Bonus will be reviewed in August 2025 | BI3: Revise price list at end of August
A4: Floor tiles | BB4: 96 | BD4: Up to 24 sq | BE4: 3000 | BI4: Check with Scott for price rise allowance
A5: Carpets | BB5: 55 | BD5: Above 24 sq | BE5: 4000
A6: Price rise allowance | BB6: 0
BB8: Shepparton | BC8: Echuca
BB9: 6 Months | BC9: 6 Months | BD9: Bonus | BF9: Floor Tiles | BG9: Wastage | BI9: Carpets | BJ9: Wastage
AE10: Windows | AO10: Sliding doors | AV10: Built-in robes/linens
A11: Single storey | B11: Dwelling area | C11: Garage area | D11: Porch area | E11: Outdoor living area | F11: Porch concrete footing | G11: Outdoor living footing | H11: Brick pier | I11: 90x90 steel columns | J11: Eaves | K11: Hip length | L11: Valley length | M11: Ridge length | N11: Perimeter walls | O11: Internal walls | P11: Plaster bulkheads | Q11: Kitchen wall bench | R11: Kitchen overhead cupboard | S11: Kitchen island bench | T11: Ens vanity bench | U11: Ens vanity basin | V11: Bath vanity bench | W11: Bath vanity basin | X11: Extra vanity bench | Y11: Extra vanity basin | Z11: Laundry bench | AA11: Internal swing door | AB11: Internal double swing door | AC11: Internal cavity sliders | AD11: Internal double cavity slider | AE11: 1006 | AF11: 1212 | AG11: 1215 | AH11: 1809 | AI11: 1812 | AJ11: 1818 | AK11: 1821 | AL11: 1824 | AM11: External swing door Entry | AN11: External swing door Garage | AO11: 2115 | AP11: 2118 | AQ11: 2121 | AR11: 2124 | AS11: 2127 | AT11: 2136 | AU11: 2155 | AV11: Up to 1800mm wide | AW11: 1800mm to 2500mm wide | AX11: 2500mm to 3000mm wide | AY11: Linen shelving - 4 shelves | AZ11: Robe shelving wth hanging rail | BA11: End panels
B12: m2 | C12: m2 | D12: m2 | E12: m2 | F12: lm | G12: lm | H12: each | I12: each | J12: lm | K12: lm | L12: lm | M12: lm | N12: lm | O12: lm | P12: lm | Q12: lm | R12: lm | S12: lm | T12: lm | U12: each | V12: lm | W12: each | X12: lm | Y12: each | Z12: lm | AA12: each | AB12: each | AC12: each | AD12: each | AE12: each | AF12: each | AG12: each | AH12: each | AI12: each | AJ12: each | AK12: each | AL12: each | AM12: each | AN12: each | AO12: each | AP12: each | AQ12: each | AR12: each | AS12: each | AT12: each | AU12: each | AV12: each | AW12: each | AX12: each | AY12: each | AZ12: each | BA12: each
A13: Byron 19 | B13: 120.71 | C13: 38.81 | D13: 5.06 | E13: 9.51 | F13: 3.8 | G13: 6.4 | H13: 1 | I13: 1 | J13: 7.09 | K13: 35.223 | L13: 9.003 | M13: 12.45 | N13: 45.17 | O13: 50.8 | P13: 3.16 | Q13: 1.5 | R13: 1.5 | S13: 2.4 | T13: 0.9 | U13: 1 | V13: 0.9 | W13: 1 | X13: 0 | Y13: 0 | Z13: 1.2 | AA13: 9 | AB13: 0 | AC13: 0 | AD13: 0 | AE13: 1 | AF13: 1 | AG13: 2 | AJ13: 1 | AP13: 1 | BB13: 270995 | BE13: =+BC13-BB13 -> -270995 | BF13: 55.87 | BG13: 1.1 | BH13: =+BG13*BF13 -> 61.457 | BI13: 49.72 | BJ13: 1.1 | BK13: =+BJ13*BI13 -> 54.692
A14: Byron 22A | B14: 142.05 | C14: 38.79 | D14: 5.06 | E14: 10.31 | H14: 1 | J14: 7.09 | K14: 35.226 | L14: 9.003 | M14: 14.97 | N14: 50.21 | O14: 54.65 | P14: 3.16 | Q14: 1.43 | R14: 1.43 | S14: 2.35 | T14: 0.9 | U14: 1 | V14: 0.9 | W14: 1 | X14: 0 | Y14: 0 | Z14: 1.2 | BB14: 289755 | BE14: =+BC14-BB14 -> -289755 | BF14: 66.31 | BG14: 1.1 | BH14: =+BG14*BF14 -> 72.941 | BI14: 61.4 | BJ14: 1.1 | BK14: =+BJ14*BI14 -> 67.54
A15: Byron 22B | B15: 154.9 | C15: 38.57 | D15: 4.18 | E15: 11.61 | H15: 2 | J15: 5.965 | K15: 37.711 | L15: 10.26 | M15: 15.34 | N15: 51.73 | O15: 64.2 | P15: 2.8 | Q15: 3.1 | R15: 1.9 | S15: 2.5 | T15: 1.2 | U15: 1 | V15: 0.9 | W15: 1 | X15: 0 | Y15: 0 | Z15: 1.2 | BB15: 294955 | BE15: =+BC15-BB15 -> -294955 | BF15: 70.17 | BG15: 1.1 | BH15: =+BG15*BF15 -> 77.187 | BI15: 60.8 | BJ15: 1.1 | BK15: =+BJ15*BI15 -> 66.88
A16: Ashwood 17 | B16: 154.9 | C16: 38.57 | D16: 4.18 | E16: 11.66 | H16: 2 | J16: 5.965 | K16: 37.711 | L16: 10.26 | M16: 15.34 | N16: 51.73 | O16: 68.35 | P16: 2.8 | Q16: 3.1 | R16: 1.9 | S16: 2.5 | T16: 1.2 | U16: 1 | V16: 0.9 | W16: 1 | X16: 0 | Y16: 0 | Z16: 1.2 | BB16: 253005 | BE16: =+BC16-BB16 -> -253005 | BF16: 51.76 | BG16: 1.1 | BH16: =+BG16*BF16 -> 56.936 | BI16: 37.9 | BJ16: 1.1 | BK16: =+BJ16*BI16 -> 41.69
A17: Ashwood 20 | B17: 170.21 | C17: 38.68 | D17: 5.08 | E17: 11.92 | H17: 1 | J17: 7.09 | K17: 37.32 | L17: 9.002 | M17: 15.66 | N17: 55.29 | O17: 67.25 | P17: 3.9 | Q17: 2.08 | R17: 2.08 | S17: 2.7 | T17: 0.9 | U17: 1 | V17: 0.9 | W17: 1 | X17: 0 | Y17: 0 | Z17: 1.2 | BB17: 276490 | BE17: =+BC17-BB17 -> -276490 | BF17: 55.5 | BG17: 1.1 | BH17: =+BG17*BF17 -> 61.05 | BI17: 61.4 | BJ17: 1.1 | BK17: =+BJ17*BI17 -> 67.54
A18: Malvern 20 | B18: 269.78 | C18: 41.25 | D18: 6.32 | E18: 13.24 | H18: 3 | J18: 6.69 | K18: 41.9 | L18: 9.02 | M18: 11.26 | N18: 51.01 | O18: 75.35 | P18: 3.75 | Q18: 2.75 | R18: 2.75 | S18: 2.7 | T18: 0.9 | U18: 1 | V18: 0.9 | W18: 1 | X18: 0 | Y18: 0 | Z18: 1.2 | BB18: 282770 | BE18: =+BC18-BB18 -> -282770 | BF18: 52.9 | BG18: 1.1 | BH18: =+BG18*BF18 -> 58.19 | BI18: 64 | BJ18: 1.1 | BK18: =+BJ18*BI18 -> 70.4
A19: Malvern 23 | B19: 201.44 | C19: 41.23 | D19: 7.14 | E19: 28.76 | H19: 4 | J19: 6.635 | K19: 45.2 | L19: 22.53 | M19: 20.6 | N19: 55.19 | O19: 92.7 | P19: 6.78 | Q19: 2.75 | R19: 2.75 | S19: 2.7 | T19: 0.9 | U19: 1 | V19: 0.9 | W19: 1 | X19: 1.2 | Y19: 1 | Z19: 1.2 | BB19: 304150 | BE19: =+BC19-BB19 -> -304150 | BF19: 69.3 | BG19: 1.1 | BH19: =+BG19*BF19 -> 76.23 | BI19: 73.3 | BJ19: 1.1 | BK19: =+BJ19*BI19 -> 80.63
A20: Malvern 25 | BB20: 332790 | BE20: =+BC20-BB20 -> -332790 | BF20: 68 | BG20: 1.1 | BH20: =+BG20*BF20 -> 74.8 | BI20: 89.1 | BJ20: 1.1 | BK20: =+BJ20*BI20 -> 98.01
B21: 228.94 | C21: 41.16 | D21: 7.38 | E21: 37.68 | H21: 4 | J21: 6.64 | K21: 47.261 | L21: 25.68 | M21: 24.465 | N21: 60 | O21: 101 | P21: 6.7 | Q21: 2.85 | R21: 2.85 | S21: 2.7 | T21: 0.9 | U21: 1 | V21: 0.9 | W21: 1 | X21: 1.33 | Y21: 1 | Z21: 1.2 | BE21: =+BC21-BB21 -> 0 | BG21: 1.1 | BH21: =+BG21*BF21 -> 0 | BJ21: 1.1 | BK21: =+BJ21*BI21 -> 0
B22: 126.99 | C22: 38.55 | D22: 5.03 | E22: 9.24 | H22: 2 | J22: 6.08 | K22: 40.75 | L22: 10.6 | M22: 9.32 | N22: 44.06 | O22: 51.35 | P22: 4.06 | Q22: 2.24 | R22: 2.24 | S22: 2.7 | T22: 0.9 | U22: 1 | V22: 0.9 | W22: 1 | X22: 0 | Y22: 0 | Z22: 1.2 | BE22: =+BC22-BB22 -> 0 | BG22: 1.1 | BH22: =+BG22*BF22 -> 0 | BJ22: 1.1 | BK22: =+BJ22*BI22 -> 0
BE23: =+BC23-BB23 -> 0 | BG23: 1.1 | BH23: =+BG23*BF23 -> 0 | BJ23: 1.1 | BK23: =+BJ23*BI23 -> 0
B24: 155.58 | C24: 37.55 | D24: 4.13 | E24: 10.65 | H24: 2 | J24: 6.9 | K24: 41.15 | L24: 11.14 | M24: 11.64 | N24: 48.69 | O24: 66.87 | P24: 2.7 | Q24: 1.8 | R24: 1.8 | S24: 2.7 | T24: 0.9 | U24: 1 | V24: 0.9 | W24: 1 | X24: 0 | Y24: 0 | Z24: 1.2 | BE24: =+BC24-BB24 -> 0 | BG24: 1.1 | BH24: =+BG24*BF24 -> 0 | BJ24: 1.1 | BK24: =+BJ24*BI24 -> 0
BO162: 375197.45 | BR162: 90 | BS162: =+#REF!*BR162 -> #REF!
BO163: 405966.8 | BR163: =+BR162 -> 90 | BS163: =+#REF!*BR163 -> #REF!
BO164: 422024.06 | BR164: =+BR163 -> 90 | BS164: =+#REF!*BR164 -> #REF!
BO165: 349552.12 | BR165: =+BR164 -> 90 | BS165: =+#REF!*BR165 -> #REF!
BO166: 380005.84 | BR166: =+BR165 -> 90 | BS166: =+#REF!*BR166 -> #REF!
BO167: 393926.2 | BR167: =+BR166 -> 90 | BS167: =+#REF!*BR167 -> #REF!
BO168: 406710.24 | BR168: =+BR167 -> 90 | BS168: =+#REF!*BR168 -> #REF!
BO169: 423263.1 | BR169: =+BR168 -> 90 | BS169: =+#REF!*BR169 -> #REF!
BO170: 472654.46 | BR170: =+BR169 -> 90 | BS170: =+#REF!*BR170 -> #REF!
BO171: 340735.79 | BR171: =+BR170 -> 90 | BS171: =+#REF!*BR171 -> #REF!
BO172: 359987.02 | BR172: =+BR171 -> 90 | BS172: =+#REF!*BR172 -> #REF!
BO173: 404153.49 | BR173: =+BR172 -> 90 | BS173: =+#REF!*BR173 -> #REF!
BO174: 323516.22 | BR174: =+BR173 -> 90 | BS174: =+#REF!*BR174 -> #REF!
... BO176: 384787.17 | BR176: =+BR175 -> 90 | BS176: =+#REF!*BR176 -> #REF!

Sheet Landscaping
C5: Seed | D5: Turf | E5: Turf with excavation
B6: 600m2 | C6: 14154.02 | D6: 16686.01 | E6: 18542.01 | H6: =+D6-C6 -> 2531.99 | J6: =+E6-D6 -> 1856
B7: 800m2 | C7: 17723.13 | D7: 21199.93 | E7: 23055.26 | H7: =+D7-C7 -> 3476.8 | J7: =+E7-D7 -> 1855.33
B8: Nature strip | E8: 1918.24
B9: Corner block | E9: 3841.6
B10: External power point | E10: =+#REF! -> #REF!
C13: Seed | D13: Turf | F13: July 2025 Pricelist - Sijo added 5 %
B14: 600m2 normal block | C14: =CEILING((C6+J6+E8)*1.36*1.05,50)+E10 -> #REF! | D14: =CEILING((E6+E8)*1.36*1.05,25)+E10 -> #REF!
B15: 600m2 corner block | C15: =+CEILING((C6+J6+E9)*1.36*1.05,25)+E10 -> #REF! | D15: =+CEILING((E6+E9)*1.36*1.05,25)+E10 -> #REF!
B16: 800m2 normal block | C16: =+CEILING((C7+J6+E8)*1.36*1.05,25)+E10 -> #REF! | D16: =+CEILING((E7+E8)*1.36*1.05,25)+E10 -> #REF!
B17: 800m2 corner block | C17: =+CEILING((C7+E9+J6)*1.36*1.05,25)+E10 -> #REF! | D17: =+CEILING((E7+E9)*1.36*1.05,25)+E10 -> #REF!

Sheet Shepparton
A1: SHEPPARTON
A2: FAST KEY
A3: HOUSE DESIGN | B3: BASE PRICE * | C3: 50sqm NATURAL CONCRETE | D3: LIFESTYLE FLOOR TILES | E3: LIFESTYLE CARPETS | F3: PACKAGE PRICE *50sqm NATURAL CONCRETE *CARPET *TILES | H3: List price | I3: Promotional | J3: Bonus | K3: 50sqm natural concrete | L3: Tiles per sqm | M3: Carpet per sqm
A4: Byron 19 | B4: =+CEILING(H4+I4+J4,5) -> 270995 | C4: =+K4 -> 7000 | D4: =+CEILING('Fast Key'!BH13*Shepparton!L4,5) -> 5900 | E4: =+CEILING('Fast Key'!BK13*Shepparton!M4,5) -> 3010 | F4: =SUM(B4:E4) -> 286905 | H4: =+'Fast Key'!BB13 -> 270995 | I4: =+'Fast Key'!BB6 -> 0 | J4: =+'Fast Key'!BD13 -> 0 | K4: =+'Fast Key'!BB3 -> 7000 | L4: =+'Fast Key'!BB4 -> 96 | M4: =+'Fast Key'!BB5 -> 55
A5: Byron 22A | B5: =+CEILING(H5+I5+J5,5) -> 289755 | C5: =+K5 -> 7000 | D5: =+CEILING('Fast Key'!BH14*Shepparton!L5,5) -> 7005 | E5: =+CEILING('Fast Key'!BK14*Shepparton!M5,5) -> 3715 | F5: =SUM(B5:E5) -> 307475 | H5: =+'Fast Key'!BB14 -> 289755 | I5: =+I4 -> 0 | J5: =+'Fast Key'!BD14 -> 0 | K5: =+K4 -> 7000 | L5: =+L4 -> 96 | M5: =+M4 -> 55
A6: Byron 22B | B6: =+CEILING(H6+I6+J6,5) -> 294955 | C6: =+K6 -> 7000 | D6: =+CEILING('Fast Key'!BH15*Shepparton!L6,5) -> 7410 | E6: =+CEILING('Fast Key'!BK15*Shepparton!M6,5) -> 3680 | F6: =SUM(B6:E6) -> 313045 | H6: =+'Fast Key'!BB15 -> 294955 | I6: =+I5 -> 0 | J6: =+'Fast Key'!BD15 -> 0 | K6: =+K5 -> 7000 | L6: =+L5 -> 96 | M6: =+M5 -> 55
A7: Ashwood 17 | B7: =+CEILING(H7+I7+J7,5) -> 253005 | C7: =+K7 -> 7000 | D7: =+CEILING('Fast Key'!BH16*Shepparton!L7,5) -> 5470 | E7: =+CEILING('Fast Key'!BK16*Shepparton!M7,5) -> 2295 | F7: =SUM(B7:E7) -> 267770 | H7: =+'Fast Key'!BB16 -> 253005 | I7: =+I6 -> 0 | J7: =+'Fast Key'!BD16 -> 0 | K7: =+K6 -> 7000 | L7: =+L6 -> 96 | M7: =+M6 -> 55
A8: Ashwood 20 | B8: =+CEILING(H8+I8+J8,5) -> 276490 | C8: =+K8 -> 7000 | D8: =+CEILING('Fast Key'!BH17*Shepparton!L8,5) -> 5865 | E8: =+CEILING('Fast Key'!BK17*Shepparton!M8,5) -> 3715 | F8: =SUM(B8:E8) -> 293070 | H8: =+'Fast Key'!BB17 -> 276490 | I8: =+I7 -> 0 | J8: =+'Fast Key'!BD17 -> 0 | K8: =+K7 -> 7000 | L8: =+L7 -> 96 | M8: =+M7 -> 55
A9: Malvern 20 | B9: =+CEILING(H9+I9+J9,5) -> 282770 | C9: =+K9 -> 7000 | D9: =+CEILING('Fast Key'!BH18*Shepparton!L9,5) -> 5590 | E9: =+CEILING('Fast Key'!BK18*Shepparton!M9,5) -> 3875 | F9: =SUM(B9:E9) -> 299235 | H9: =+'Fast Key'!BB18 -> 282770 | I9: =+I8 -> 0 | J9: =+'Fast Key'!BD18 -> 0 | K9: =+K8 -> 7000 | L9: =+L8 -> 96 | M9: =+M8 -> 55
A10: Malvern 23 | B10: =+CEILING(H10+I10+J10,5) -> 304150 | C10: =+K10 -> 7000 | D10: =+CEILING('Fast Key'!BH19*Shepparton!L10,5) -> 7320 | E10: =+CEILING('Fast Key'!BK19*Shepparton!M10,5) -> 4435 | F10: =SUM(B10:E10) -> 322905 | H10: =+'Fast Key'!BB19 -> 304150 | I10: =+I9 -> 0 | J10: =+'Fast Key'!BD19 -> 0 | K10: =+K9 -> 7000 | L10: =+L9 -> 96 | M10: =+M9 -> 55
A11: Malvern 25 | B11: =+CEILING(H11+I11+J11,5) -> 332790 | C11: =+K11 -> 7000 | D11: =+CEILING('Fast Key'!BH20*Shepparton!L11,5) -> 7185 | E11: =+CEILING('Fast Key'!BK20*Shepparton!M11,5) -> 5395 | F11: =SUM(B11:E11) -> 352370 | H11: =+'Fast Key'!BB20 -> 332790 | I11: =+I10 -> 0 | J11: =+'Fast Key'!BD20 -> 0 | K11: =+K10 -> 7000 | L11: =+L10 -> 96 | M11: =+M10 -> 55
B12: =+CEILING(H12+I12+J12,10) -> 0 | C12: =+K12 -> 7000 | D12: =+CEILING('Fast Key'!BH21*Shepparton!L12,5) -> 0 | E12: =+CEILING('Fast Key'!BK21*Shepparton!M12,5) -> 0 | F12: =SUM(B12:E12) -> 7000 | H12: =+'Fast Key'!BB21 -> 0 | I12: =+I11 -> 0 | J12: =+'Fast Key'!BD21 -> 0 | K12: =+K11 -> 7000 | L12: =+L11 -> 96 | M12: =+M11 -> 55
B13: =+CEILING(H13+I13+J13,10) -> 0 | C13: =+K13 -> 7000 | D13: =+CEILING('Fast Key'!BH22*Shepparton!L13,5) -> 0 | E13: =+CEILING('Fast Key'!BK22*Shepparton!M13,5) -> 0 | F13: =SUM(B13:E13) -> 7000 | H13: =+'Fast Key'!BB22 -> 0 | I13: =+I12 -> 0 | J13: =+'Fast Key'!BD22 -> 0 | K13: =+K12 -> 7000 | L13: =+L12 -> 96 | M13: =+M12 -> 55
B14: =+CEILING(H14+I14+J14,10) -> 0 | C14: =+K14 -> 7000 | D14: =+CEILING('Fast Key'!BH23*Shepparton!L14,5) -> 0 | E14: =+CEILING('Fast Key'!BK23*Shepparton!M14,5) -> 0 | F14: =SUM(B14:E14) -> 7000 | H14: =+'Fast Key'!BB23 -> 0 | I14: =+I13 -> 0 | J14: =+'Fast Key'!BD23 -> 0 | K14: =+K13 -> 7000 | L14: =+L13 -> 96 | M14: =+M13 -> 55
B15: =+CEILING(H15+I15+J15,10) -> 0 | C15: =+K15 -> 7000 | D15: =+CEILING('Fast Key'!BH24*Shepparton!L15,5) -> 0 | E15: =+CEILING('Fast Key'!BK24*Shepparton!M15,5) -> 0 | F15: =SUM(B15:E15) -> 7000 | H15: =+'Fast Key'!BB24 -> 0 | I15: =+I14 -> 0 | J15: =+'Fast Key'!BD24 -> 0 | K15: =+K14 -> 7000 | L15: =+L14 -> 96 | M15: =+M14 -> 55
B16: =+CEILING(H16+I16+J16,10) -> 0 | C16: =+K16 -> 7000 | D16: =+CEILING('Fast Key'!BH25*Shepparton!L16,5) -> 0 | E16: =+CEILING('Fast Key'!BK25*Shepparton!M16,5) -> 0 | F16: =SUM(B16:E16) -> 7000 | H16: =+'Fast Key'!BB25 -> 0 | I16: =+I15 -> 0 | J16: =+'Fast Key'!BD25 -> 0 | K16: =+K15 -> 7000 | L16: =+L15 -> 96 | M16: =+M15 -> 55
A18: BASE PRICE INCLUDES: | E18: BASE PRICE DOES NOT INCLUDE:
A19: *SEWER, STORMWATER AND POWER | E19: *SITE PIERING
A20: TO A 700m2 BLOCK | E20: *RAISED PORTICO
A21: *20m TEMP FENCING | E21: *TILES & CARPET
A22: *'MD' CLASS SLAB | E22: *EXTERNAL PAVING
E23: *EAVES

Sheet Investor
A1: INVESTOR PRICE LIST VALID UP TO DECEMBER 2025
A2: HOUSE DESIGN | B2: BASE PRICE * | C2: 60sqm NATURAL CONCRETE | D2: ASPIRE FLOOR TILES | E2: ASPIRE CARPET | F2: ROLLER BLINDS TO ALL WINDOWS AND SLIDING DOORS | G2: TV ANTENNA | H2: SPLIT SYSTEM TO FAMILY ROOM | I2: WALL MOUNTED CLOTHESLINE | J2: COLORBOND LETTER BOX | K2: PACKAGE PRICE | O2: 60sqm natural concrete | P2: Aspire Tiles per sqm | Q2: Aspire Carpet per sqm
A3: Kiewa 15 | B3: =+CEILING(N3+M3,10) -> 6000 | C3: =+O3 -> 8400 | D3: =+CEILING('Fast Key'!BH144*Investor!P3,5) -> 0 | E3: =+CEILING('Fast Key'!BK144*Investor!Q3,5) -> 0 | F3: =9*195 -> 1755 | G3: =+#REF! -> #REF! | H3: INCLUDED | I3: =+#REF! -> #REF! | J3: =+#REF! -> #REF! | K3: =SUM(B3:J3) -> #REF! | M3: 6000 | N3: =+'Fast Key'!BB144 -> 0 | O3: =60*140 -> 8400 | P3: 95 | Q3: 56
A4: Kiewa 17 | B4: =+CEILING(N4+M4,10) -> 6000 | C4: =+O4 -> 8400 | D4: =+CEILING('Fast Key'!BH145*Investor!P4,5) -> 0 | E4: =+CEILING('Fast Key'!BK145*Investor!Q4,5) -> 0 | F4: =10*195 -> 1950 | G4: =+G3 -> #REF! | H4: INCLUDED | I4: =+I3 -> #REF! | J4: =+J3 -> #REF! | K4: =SUM(B4:J4) -> #REF! | M4: =+M3 -> 6000 | N4: =+'Fast Key'!BB145 -> 0 | O4: =+O3 -> 8400 | P4: =+P3 -> 95 | Q4: =+Q3 -> 56
A5: Kiewa 18 | B5: =+CEILING(N5+M5,10) -> 6000 | C5: =+O5 -> 8400 | D5: =+CEILING('Fast Key'!BH146*Investor!P5,5) -> 0 | E5: =+CEILING('Fast Key'!BK146*Investor!Q5,5) -> 0 | F5: =11*195 -> 2145 | G5: =+G4 -> #REF! | H5: INCLUDED | I5: =+I4 -> #REF! | J5: =+J4 -> #REF! | K5: =SUM(B5:J5) -> #REF! | M5: =+M4 -> 6000 | N5: =+'Fast Key'!BB146 -> 0 | O5: =+O4 -> 8400 | P5: =+P4 -> 95 | Q5: =+Q4 -> 56
A6: Kiewa 21 | B6: =+CEILING(N6+M6,10) -> 6000 | C6: =+O6 -> 8400 | D6: =+CEILING('Fast Key'!BH147*Investor!P6,5) -> 0 | E6: =+CEILING('Fast Key'!BK147*Investor!Q6,5) -> 0 | F6: =12*195 -> 2340 | G6: =+G5 -> #REF! | H6: 4150 | I6: =+I5 -> #REF! | J6: =+J5 -> #REF! | K6: =SUM(B6:J6) -> #REF! | M6: =+M5 -> 6000 | N6: =+'Fast Key'!BB147 -> 0 | O6: =+O5 -> 8400 | P6: =+P5 -> 95 | Q6: =+Q5 -> 56
A7: Prices based on a Standard Façade
A9: ## THESE RATES APPLY ONLY FOR INVESTORS, NOT OWNER-OCCUPIERS ##
A10: ## FOR OWNER-OCCUPIERS PLEASE USE THE MAIN PRICE LIST ##
A12: LANDSCAPING PRICES
A13: Size | C13: Seed | D13: Turf
A14: =+Landscaping!B14 -> 600m2 normal block | C14: =+Landscaping!C14 -> #REF! | D14: =+Landscaping!D14 -> #REF! | F14: Includes automated sprinkler sytem
A15: =+Landscaping!B15 -> 600m2 corner block | C15: =+Landscaping!C15 -> #REF! | D15: =+Landscaping!D15 -> #REF! | F15: Credit $600 to go down to a manual system
A16: =+Landscaping!B16 -> 800m2 normal block | C16: =+Landscaping!C16 -> #REF! | D16: =+Landscaping!D16 -> #REF!
A17: =+Landscaping!B17 -> 800m2 corner block | C17: =+Landscaping!C17 -> #REF! | D17: =+Landscaping!D17 -> #REF!

Sheet Echuca
A1: ECHUCA
A2: LIFESTYLE SINGLE STOREY PRICE LIST VALID UP TO DEC 2025
A3: HOUSE DESIGN | B3: BASE PRICE * | C3: 50sqm NATURAL CONCRETE | D3: LIFESTYLE FLOOR TILES | E3: LIFESTYLE CARPETS | F3: PACKAGE PRICE *50sqm NATURAL CONCRETE *CARPET *TILES | G3: PRICE TO ADD EAVES | I3: List price | J3: Promotional | K3: Bonus | L3: 50sqm natural concrete | M3: Tiles per sqm | N3: Carpet per sqm | O3: Eaves per lm
A4: Adelaide 18 | B4: =+CEILING(I4+J4+K4,10) -> 0 | C4: =+L4 -> #REF! | D4: =+Shepparton!D4 -> 5900 | E4: =+Shepparton!E4 -> 3010 | F4: =SUM(B4:E4) -> #REF! | G4: =+Shepparton!#REF! -> #REF! | I4: =+'Fast Key'!BC13 -> 0 | J4: =+'Fast Key'!BB6 -> 0 | K4: =+'Fast Key'!BD13 -> 0 | L4: =50*'2.TRAVEL'!#REF! -> #REF! | M4: 103 | N4: 60 | O4: 65
A5: Adelaide 21 | B5: =+CEILING(I5+J5+K5,10) -> 0 | C5: =+L5 -> #REF! | D5: =+Shepparton!D5 -> 7005 | E5: =+Shepparton!E5 -> 3715 | F5: =SUM(B5:E5) -> #REF! | G5: =+Shepparton!#REF! -> #REF! | I5: =+'Fast Key'!BC14 -> 0 | J5: =+J4 -> 0 | K5: =+'Fast Key'!BD14 -> 0 | L5: =+L4 -> #REF! | M5: =+M4 -> 103 | N5: =+N4 -> 60 | O5: =+O4 -> 65
A6: Adelaide 22A | B6: =+CEILING(I6+J6+K6,10) -> 0 | C6: =+L6 -> #REF! | D6: =+Shepparton!D6 -> 7410 | E6: =+Shepparton!E6 -> 3680 | F6: =SUM(B6:E6) -> #REF! | G6: =+Shepparton!#REF! -> #REF! | I6: =+'Fast Key'!BC15 -> 0 | J6: =+J5 -> 0 | K6: =+'Fast Key'!BD15 -> 0 | L6: =+L5 -> #REF! | M6: =+M5 -> 103 | N6: =+N5 -> 60 | O6: =+O5 -> 65
A7: Adelaide 22B | B7: =+CEILING(I7+J7+K7,10) -> 0 | C7: =+L7 -> #REF! | D7: =+Shepparton!D7 -> 5470 | E7: =+Shepparton!E7 -> 2295 | F7: =SUM(B7:E7) -> #REF! | G7: =+Shepparton!#REF! -> #REF! | I7: =+'Fast Key'!BC16 -> 0 | J7: =+J6 -> 0 | K7: =+'Fast Key'!BD16 -> 0 | L7: =+L6 -> #REF! | M7: =+M6 -> 103 | N7: =+N6 -> 60 | O7: =+O6 -> 65
A8: Adelaide 24 | B8: =+CEILING(I8+J8+K8,10) -> 0 | C8: =+L8 -> #REF! | D8: =+Shepparton!D8 -> 5865 | E8: =+Shepparton!E8 -> 3715 | F8: =SUM(B8:E8) -> #REF! | G8: =+Shepparton!#REF! -> #REF! | I8: =+'Fast Key'!BC17 -> 0 | J8: =+J7 -> 0 | K8: =+'Fast Key'!BD17 -> 0 | L8: =+L7 -> #REF! | M8: =+M7 -> 103 | N8: =+N7 -> 60 | O8: =+O7 -> 65
A9: Ashfield 24 | B9: =+CEILING(I9+J9+K9,10) -> 0 | C9: =+L9 -> #REF! | D9: =+Shepparton!D9 -> 5590 | E9: =+Shepparton!E9 -> 3875 | F9: =SUM(B9:E9) -> #REF! | G9: =+Shepparton!#REF! -> #REF! | I9: =+'Fast Key'!BC18 -> 0 | J9: =+J8 -> 0 | K9: =+'Fast Key'!BD18 -> 0 | L9: =+L8 -> #REF! | M9: =+M8 -> 103 | N9: =+N8 -> 60 | O9: =+O8 -> 65
A10: Ashfield 30 | B10: =+CEILING(I10+J10+K10,10) -> 0 | C10: =+L10 -> #REF! | D10: =+Shepparton!D10 -> 7320 | E10: =+Shepparton!E10 -> 4435 | F10: =SUM(B10:E10) -> #REF! | G10: =+Shepparton!#REF! -> #REF! | I10: =+'Fast Key'!BC19 -> 0 | J10: =+J9 -> 0 | K10: =+'Fast Key'!BD19 -> 0 | L10: =+L9 -> #REF! | M10: =+M9 -> 103 | N10: =+N9 -> 60 | O10: =+O9 -> 65
A11: Ashfield 30A | B11: =+CEILING(I11+J11+K11,10) -> 0 | C11: =+L11 -> #REF! | D11: =+Shepparton!D11 -> 7185 | E11: =+Shepparton!E11 -> 5395 | F11: =SUM(B11:E11) -> #REF! | G11: =+Shepparton!#REF! -> #REF! | I11: =+'Fast Key'!BC20 -> 0 | J11: =+J10 -> 0 | K11: =+'Fast Key'!BD20 -> 0 | L11: =+L10 -> #REF! | M11: =+M10 -> 103 | N11: =+N10 -> 60 | O11: =+O10 -> 65
A12: Ashfield 34 | B12: =+CEILING(I12+J12+K12,10) -> 0 | C12: =+L12 -> #REF! | D12: =+Shepparton!D12 -> 0 | E12: =+Shepparton!E12 -> 0 | F12: =SUM(B12:E12) -> #REF! | G12: =+Shepparton!#REF! -> #REF! | I12: =+'Fast Key'!BC21 -> 0 | J12: =+J11 -> 0 | K12: =+'Fast Key'!BD21 -> 0 | L12: =+L11 -> #REF! | M12: =+M11 -> 103 | N12: =+N11 -> 60 | O12: =+O11 -> 65
A13: Ashley 19 | B13: =+CEILING(I13+J13+K13,10) -> 0 | C13: =+L13 -> #REF! | D13: =+Shepparton!D13 -> 0 | E13: =+Shepparton!E13 -> 0 | F13: =SUM(B13:E13) -> #REF! | G13: =+Shepparton!#REF! -> #REF! | I13: =+'Fast Key'!BC22 -> 0 | J13: =+J12 -> 0 | K13: =+'Fast Key'!BD22 -> 0 | L13: =+L12 -> #REF! | M13: =+M12 -> 103 | N13: =+N12 -> 60 | O13: =+O12 -> 65
A14: Ashley 21 | B14: =+CEILING(I14+J14+K14,10) -> 0 | C14: =+L14 -> #REF! | D14: =+Shepparton!D14 -> 0 | E14: =+Shepparton!E14 -> 0 | F14: =SUM(B14:E14) -> #REF! | G14: =+Shepparton!#REF! -> #REF! | I14: =+'Fast Key'!BC23 -> 0 | J14: =+J13 -> 0 | K14: =+'Fast Key'!BD23 -> 0 | L14: =+L13 -> #REF! | M14: =+M13 -> 103 | N14: =+N13 -> 60 | O14: =+O13 -> 65
A15: Ashley 22 | B15: =+CEILING(I15+J15+K15,10) -> 0 | C15: =+L15 -> #REF! | D15: =+Shepparton!D15 -> 0 | E15: =+Shepparton!E15 -> 0 | F15: =SUM(B15:E15) -> #REF! | G15: =+Shepparton!#REF! -> #REF! | I15: =+'Fast Key'!BC24 -> 0 | J15: =+J13 -> 0 | K15: =+'Fast Key'!BD24 -> 0 | L15: =+L13 -> #REF! | M15: =+M13 -> 103 | N15: =+N13 -> 60 | O15: =+O13 -> 65
A16: Ashley 22A | B16: =+CEILING(I16+J16+K16,10) -> 0 | C16: =+L16 -> #REF! | D16: =+Shepparton!D16 -> 0 | E16: =+Shepparton!E16 -> 0 | F16: =SUM(B16:E16) -> #REF! | G16: =+Shepparton!#REF! -> #REF! | I16: =+'Fast Key'!BC25 -> 0 | J16: =+J14 -> 0 | K16: =+'Fast Key'!BD25 -> 0 | L16: =+L14 -> #REF! | M16: =+M14 -> 103 | N16: =+N14 -> 60 | O16: =+O14 -> 65
A17: Ashley 24 | B17: =+CEILING(I17+J17+K17,10) -> 0 | C17: =+L17 -> #REF! | D17: =+Shepparton!#REF! -> #REF! | E17: =+Shepparton!#REF! -> #REF! | F17: =SUM(B17:E17) -> #REF! | G17: =+Shepparton!#REF! -> #REF! | I17: =+'Fast Key'!BC26 -> 0 | J17: =+J15 -> 0 | K17: =+'Fast Key'!BD26 -> 0 | L17: =+L15 -> #REF! | M17: =+M15 -> 103 | N17: =+N15 -> 60 | O17: =+O15 -> 65
A18: Ashley 25 | B18: =+CEILING(I18+J18+K18,10) -> 0 | C18: =+L18 -> #REF! | D18: =+Shepparton!#REF! -> #REF! | E18: =+Shepparton!#REF! -> #REF! | F18: =SUM(B18:E18) -> #REF! | G18: =+Shepparton!#REF! -> #REF! | I18: =+'Fast Key'!BC27 -> 0 | J18: =+J17 -> 0 | K18: =+'Fast Key'!BD27 -> 0 | L18: =+L17 -> #REF! | M18: =+M17 -> 103 | N18: =+N17 -> 60 | O18: =+O17 -> 65
A19: Ashley 25A | B19: =+CEILING(I19+J19+K19,10) -> 0 | C19: =+L19 -> #REF! | D19: =+Shepparton!#REF! -> #REF! | E19: =+Shepparton!#REF! -> #REF! | F19: =SUM(B19:E19) -> #REF! | G19: =+Shepparton!#REF! -> #REF! | I19: =+'Fast Key'!BC28 -> 0 | J19: =+J18 -> 0 | K19: =+'Fast Key'!BD28 -> 0 | L19: =+L18 -> #REF! | M19: =+M18 -> 103 | N19: =+N18 -> 60 | O19: =+O18 -> 65
A20: Ashley 26 | B20: =+CEILING(I20+J20+K20,10) -> 0 | C20: =+L20 -> #REF! | D20: =+Shepparton!#REF! -> #REF! | E20: =+Shepparton!#REF! -> #REF! | F20: =SUM(B20:E20) -> #REF! | G20: =+Shepparton!#REF! -> #REF! | I20: =+'Fast Key'!BC29 -> 0 | J20: =+J19 -> 0 | K20: =+'Fast Key'!BD29 -> 0 | L20: =+L19 -> #REF! | M20: =+M19 -> 103 | N20: =+N19 -> 60 | O20: =+O19 -> 65
A21: Ashley 27 | B21: =+CEILING(I21+J21+K21,10) -> 0 | C21: =+L21 -> #REF! | D21: =+Shepparton!#REF! -> #REF! | E21: =+Shepparton!#REF! -> #REF! | F21: =SUM(B21:E21) -> #REF! | G21: =+Shepparton!#REF! -> #REF! | I21: =+'Fast Key'!BC30 -> 0 | J21: =+J20 -> 0 | K21: =+'Fast Key'!BD30 -> 0 | L21: =+L20 -> #REF! | M21: =+M20 -> 103 | N21: =+N20 -> 60 | O21: =+O20 -> 65
A22: Ashley 28 | B22: =+CEILING(I22+J22+K22,10) -> 0 | C22: =+L22 -> #REF! | D22: =+Shepparton!#REF! -> #REF! | E22: =+Shepparton!#REF! -> #REF! | F22: =SUM(B22:E22) -> #REF! | G22: =+Shepparton!#REF! -> #REF! | I22: =+'Fast Key'!BC31 -> 0 | J22: =+J21 -> 0 | K22: =+'Fast Key'!BD31 -> 0 | L22: =+L21 -> #REF! | M22: =+M21 -> 103 | N22: =+N21 -> 60 | O22: =+O21 -> 65
A23: Ashley 28A | B23: =+CEILING(I23+J23+K23,10) -> 0 | C23: =+L23 -> #REF! | D23: =+Shepparton!#REF! -> #REF! | E23: =+Shepparton!#REF! -> #REF! | F23: =SUM(B23:E23) -> #REF! | G23: =+Shepparton!#REF! -> #REF! | I23: =+'Fast Key'!BC32 -> 0 | J23: =+J22 -> 0 | K23: =+'Fast Key'!BD32 -> 0 | L23: =+L22 -> #REF! | M23: =+M22 -> 103 | N23: =+N22 -> 60 | O23: =+O22 -> 65
A24: Ballina 24 | B24: =+CEILING(I24+J24+K24,10) -> 0 | C24: =+L24 -> #REF! | D24: =+Shepparton!#REF! -> #REF! | E24: =+Shepparton!#REF! -> #REF! | F24: =SUM(B24:E24) -> #REF! | G24: =+Shepparton!#REF! -> #REF! | I24: =+'Fast Key'!BC33 -> 0 | J24: =+J23 -> 0 | K24: =+'Fast Key'!BD33 -> 0 | L24: =+L23 -> #REF! | M24: =+M23 -> 103 | N24: =+N23 -> 60 | O24: =+O23 -> 65
A25: Ballina 30 | B25: =+CEILING(I25+J25+K25,10) -> 0 | C25: =+L25 -> #REF! | D25: =+Shepparton!#REF! -> #REF! | E25: =+Shepparton!#REF! -> #REF! | F25: =SUM(B25:E25) -> #REF! | G25: =+Shepparton!#REF! -> #REF! | I25: =+'Fast Key'!BC34 -> 0 | J25: =+J24 -> 0 | K25: =+'Fast Key'!BD34 -> 0 | L25: =+L24 -> #REF! | M25: =+M24 -> 103 | N25: =+N24 -> 60 | O25: =+O24 -> 65
A26: Ballina 30A | B26: =+CEILING(I26+J26+K26,10) -> 0 | C26: =+L26 -> #REF! | D26: =+Shepparton!#REF! -> #REF! | E26: =+Shepparton!#REF! -> #REF! | F26: =SUM(B26:E26) -> #REF! | G26: =+Shepparton!#REF! -> #REF! | I26: =+'Fast Key'!BC35 -> 0 | J26: =+J25 -> 0 | K26: =+'Fast Key'!BD35 -> 0 | L26: =+L25 -> #REF! | M26: =+M25 -> 103 | N26: =+N25 -> 60 | O26: =+O25 -> 65
A27: Ballina 33 | B27: =+CEILING(I27+J27+K27,10) -> 0 | C27: =+L27 -> #REF! | D27: =+Shepparton!#REF! -> #REF! | E27: =+Shepparton!#REF! -> #REF! | F27: =SUM(B27:E27) -> #REF! | G27: =+Shepparton!#REF! -> #REF! | I27: =+'Fast Key'!BC36 -> 0 | J27: =+J25 -> 0 | K27: =+'Fast Key'!BD36 -> 0 | L27: =+L25 -> #REF! | M27: =+M25 -> 103 | N27: =+N25 -> 60 | O27: =+O25 -> 65
A28: Ballina 39 | B28: =+CEILING(I28+J28+K28,10) -> 0 | C28: =+L28 -> #REF! | D28: =+Shepparton!#REF! -> #REF! | E28: =+Shepparton!#REF! -> #REF! | F28: =SUM(B28:E28) -> #REF! | G28: =+Shepparton!#REF! -> #REF! | I28: =+'Fast Key'!BC37 -> 0 | J28: =+J27 -> 0 | K28: =+'Fast Key'!BD37 -> 0 | L28: =+L27 -> #REF! | M28: =+M27 -> 103 | N28: =+N27 -> 60 | O28: =+O27 -> 65
A29: =+'Fast Key'!A38 -> 0 | B29: =+CEILING(I29+J29+K29,10) -> 0 | C29: =+L29 -> #REF! | D29: =+Shepparton!#REF! -> #REF! | E29: =+Shepparton!#REF! -> #REF! | F29: =SUM(B29:E29) -> #REF! | G29: =+Shepparton!#REF! -> #REF! | I29: =+'Fast Key'!BC38 -> 0 | J29: =+J28 -> 0 | K29: =+'Fast Key'!BD38 -> 0 | L29: =+L28 -> #REF! | M29: =+M28 -> 103 | N29: =+N28 -> 60 | O29: =+O28 -> 65
A30: =+'Fast Key'!A39 -> 0 | B30: =+CEILING(I30+J30+K30,10) -> 0 | C30: =+L30 -> #REF! | D30: =+Shepparton!#REF! -> #REF! | E30: =+Shepparton!#REF! -> #REF! | F30: =SUM(B30:E30) -> #REF! | G30: =+Shepparton!#REF! -> #REF! | I30: =+'Fast Key'!BC39 -> 0 | J30: =+J29 -> 0 | K30: =+'Fast Key'!BD39 -> 0 | L30: =+L29 -> #REF! | M30: =+M29 -> 103 | N30: =+N29 -> 60 | O30: =+O29 -> 65
A31: =+'Fast Key'!A40 -> 0 | B31: =+CEILING(I31+J31+K31,10) -> 0 | C31: =+L31 -> #REF! | D31: =+Shepparton!#REF! -> #REF! | E31: =+Shepparton!#REF! -> #REF! | F31: =SUM(B31:E31) -> #REF! | G31: =+Shepparton!#REF! -> #REF! | I31: =+'Fast Key'!BC40 -> 0 | J31: =+J30 -> 0 | K31: =+'Fast Key'!BD40 -> 0 | L31: =+L30 -> #REF! | M31: =+M30 -> 103 | N31: =+N30 -> 60 | O31: =+O30 -> 65
A32: Bayview 23 | B32: =+CEILING(I32+J32+K32,10) -> 0 | C32: =+L32 -> #REF! | D32: =+Shepparton!#REF! -> #REF! | E32: =+Shepparton!#REF! -> #REF! | F32: =SUM(B32:E32) -> #REF! | G32: =+Shepparton!#REF! -> #REF! | I32: =+'Fast Key'!BC41 -> 0 | J32: =+J31 -> 0 | K32: =+'Fast Key'!BD41 -> 0 | L32: =+L31 -> #REF! | M32: =+M31 -> 103 | N32: =+N31 -> 60 | O32: =+O31 -> 65
A33: Bayview 26 | B33: =+CEILING(I33+J33+K33,10) -> 0 | C33: =+L33 -> #REF! | D33: =+Shepparton!#REF! -> #REF! | E33: =+Shepparton!#REF! -> #REF! | F33: =SUM(B33:E33) -> #REF! | G33: =+Shepparton!#REF! -> #REF! | I33: =+'Fast Key'!BC42 -> 0 | J33: =+J32 -> 0 | K33: =+'Fast Key'!BD42 -> 0 | L33: =+L32 -> #REF! | M33: =+M32 -> 103 | N33: =+N32 -> 60 | O33: =+O32 -> 65
A34: Bayview 30 | B34: =+CEILING(I34+J34+K34,10) -> 0 | C34: =+L34 -> #REF! | D34: =+Shepparton!#REF! -> #REF! | E34: =+Shepparton!#REF! -> #REF! | F34: =SUM(B34:E34) -> #REF! | G34: =+Shepparton!#REF! -> #REF! | I34: =+'Fast Key'!BC43 -> 0 | J34: =+J33 -> 0 | K34: =+'Fast Key'!BD43 -> 0 | L34: =+L33 -> #REF! | M34: =+M33 -> 103 | N34: =+N33 -> 60 | O34: =+O33 -> 65
A35: Bondi 25 | B35: =+CEILING(I35+J35+K35,10) -> 0 | C35: =+L35 -> #REF! | D35: =+Shepparton!#REF! -> #REF! | E35: =+Shepparton!#REF! -> #REF! | F35: =SUM(B35:E35) -> #REF! | G35: =+Shepparton!#REF! -> #REF! | I35: =+'Fast Key'!BC44 -> 0 | J35: =+J34 -> 0 | K35: =+'Fast Key'!BD44 -> 0 | L35: =+L34 -> #REF! | M35: =+M34 -> 103 | N35: =+N34 -> 60 | O35: =+O34 -> 65
A36: Bondi 31 | B36: =+CEILING(I36+J36+K36,10) -> 0 | C36: =+L36 -> #REF! | D36: =+Shepparton!#REF! -> #REF! | E36: =+Shepparton!#REF! -> #REF! | F36: =SUM(B36:E36) -> #REF! | G36: =+Shepparton!#REF! -> #REF! | I36: =+'Fast Key'!BC45 -> 0 | J36: =+J35 -> 0 | K36: =+'Fast Key'!BD45 -> 0 | L36: =+L35 -> #REF! | M36: =+M35 -> 103 | N36: =+N35 -> 60 | O36: =+O35 -> 65
A37: Bondi 36 | B37: =+CEILING(I37+J37+K37,10) -> 0 | C37: =+L37 -> #REF! | D37: =+Shepparton!#REF! -> #REF! | E37: =+Shepparton!#REF! -> #REF! | F37: =SUM(B37:E37) -> #REF! | G37: =+Shepparton!#REF! -> #REF! | I37: =+'Fast Key'!BC46 -> 0 | J37: =+J36 -> 0 | K37: =+'Fast Key'!BD46 -> 0 | L37: =+L36 -> #REF! | M37: =+M36 -> 103 | N37: =+N36 -> 60 | O37: =+O36 -> 65
A38: Cambridge 22 | B38: =+CEILING(I38+J38+K38,10) -> 0 | C38: =+L38 -> #REF! | D38: =+Shepparton!#REF! -> #REF! | E38: =+Shepparton!#REF! -> #REF! | F38: =SUM(B38:E38) -> #REF! | G38: =+Shepparton!#REF! -> #REF! | I38: =+'Fast Key'!BC47 -> 0 | J38: =+J37 -> 0 | K38: =+'Fast Key'!BD47 -> 0 | L38: =+L37 -> #REF! | M38: =+M37 -> 103 | N38: =+N37 -> 60 | O38: =+O37 -> 65
A39: Cambridge 24 | B39: =+CEILING(I39+J39+K39,10) -> 0 | C39: =+L39 -> #REF! | D39: =+Shepparton!#REF! -> #REF! | E39: =+Shepparton!#REF! -> #REF! | F39: =SUM(B39:E39) -> #REF! | G39: =+Shepparton!#REF! -> #REF! | I39: =+'Fast Key'!BC48 -> 0 | J39: =+J38 -> 0 | K39: =+'Fast Key'!BD48 -> 0 | L39: =+L38 -> #REF! | M39: =+M38 -> 103 | N39: =+N38 -> 60 | O39: =+O38 -> 65
A40: Cambridge 26 | B40: =+CEILING(I40+J40+K40,10) -> 0 | C40: =+L40 -> #REF! | D40: =+Shepparton!#REF! -> #REF! | E40: =+Shepparton!#REF! -> #REF! | F40: =SUM(B40:E40) -> #REF! | G40: =+Shepparton!#REF! -> #REF! | I40: =+'Fast Key'!BC49 -> 0 | J40: =+J39 -> 0 | K40: =+'Fast Key'!BD49 -> 0 | L40: =+L39 -> #REF! | M40: =+M39 -> 103 | N40: =+N39 -> 60 | O40: =+O39 -> 65
...

Sheet Value Packs
B2: LIFESTYLE VALUE PACKS - NOV 2024
B4: ENTRANCE PACK
B5: 1200mm x 2040mm timber glass front door | C5: 1340
B6: Nexion Trilock handle | C6: 175
B7: Total | C7: =SUM(C5:C6) -> 1515
B9: KITCHEN CABINETRY PACK
B10: 2 Banks of drawers | C10: 660
B11: Twin bin in drawer with drawer below | C11: 250
B12: Fridge overhead cupboard | C12: 960 | E12: 1000mm with one side panel
B13: Total | C13: =SUM(C10:C12) -> 1870
B15: KITCHEN APPLIANCE PACK
B16: 90cm Inbuilt oven & gas cooktop | C16: 1355
B17: 70cm Intergrated rangehood | C17: 165
B18: Water point to fridge | C18: 200
B19: Total | C19: =SUM(C16:C18) -> 1720
B21: KITCHEN BENCHTOP PACK
B22: 20mm Stone benchtop | C22: 3625 | E22: (3.2m wall bench & 2.7m island)
B23: Undermount sink | C23: 355
B24: Total | C24: =SUM(C22:C23) -> 3980
B26: BATHROOM/ENSUITE INDULGENT PACK
B27: 20mm Stone vanity benchtops | C27: 1350 | E27: (up to 1 x 1800mm & 1 x 900mm)
B28: Above counter basins with tower mixers | C28: 450 | E28: x3
B29: Tiled recess shelf to showers | C29: 800
B30: Dual shower head to ensuite | C30: 250
B31: Total | C31: =SUM(C27:C30) -> 2850
B33: LAUNDRY INDULGENT PACK
B34: Extend bench & cabinets up to 2m | C34: 2800
B35: Pull out clothesbasket | C35: 220
B36: Total | C36: =SUM(C34:C35) -> 3020
B38: LIGHTING PACK 1
B39: 30 X LED downlights | C39: 2550 | E39: replaces 15 light points
B40: Total | C40: =SUM(C39:C39) -> 2550
B42: LIGHTING PACK 2
B43: 30 X LED downlights | C43: 2550 | E43: replaces 15 light points
B44: 3 X Pendant lights above island bench | C44: 1155 | E44: 220 per pendant
B45: Total | C45: =SUM(C43:C44) -> 3705
B47: LIGHTING PACK 3
B48: 30 X LED downlights | C48: 2550 | E48: replaces 15 light points
B49: 3 X Pendant lights above island bench | C49: =+C44 -> 1155 | E49: 220 per pendant
B50: 3 X Wall mounted feature lights to the front façade with motion sensor | C50: 1290
...

Sheet Sandown 32 Display
B4: ABN: 50 105 889 745
B5: 7961 Goulburn Valley Hwy | E5: Telephone 5823 1859
B6: P O BOX 922 | E6: Display Home 5832 6082
B7: SHEPPARTON VIC 3632 | E7: DB-U 9856
B9: Dear | C9: =+C48 -> 0
B11: RE: PRELIMINARY PRICING
B13: Thank you for your interest in building a new home with Cavalier Homes Goulburn Valley, we greatly
B14: appreciate the opportunity to work with you designing and building your new home.
B16: Please find attached the preliminary pricing to build a house on your land at
B17: =+C52 -> 0
B19: This preliminary pricing is provided as a guide and is subject to review after 30 days or before this
B20: time if a new price list is released in the interim.
B22: If you are pleased with the preliminary price, we can then provide a firm price once you have paid an
B23: initial preliminary service fee of $2,000 - (this will secure the price as per the terms and conditions
B24: of the Cavalier Homes Goulburn Valley Ground Work document which we will discuss further should
B25: you wish to proceed to the next stage).
B27: Once the initial preliminary service fee is received, we will arrange to have working drawings drafted
B28: which will show you fully detailed plan of the interior and exterior of your home.
B29: We will also engage an independent, qualified engineer to provide a slab design based on your home
B30: design and the results of the soil test inspection carried out on your block.
B32: As discussed, we will provide you with a final fixed price once the following are completed:
B33: The colour selections
... B55: PRE- CONSTRUCTION
B56: Soil test and site inspection of your block | D56: Included
B57: Independent qualified engineer designed slab | D57: Included
B58: Rescode investigation | D58: Included
B59: Building permit and associated fees (does not include planning permit) | D59: Included
B60: Development application for NSW jobs | D60: Included
B61: Builder's insurances | D61: Included
B62: Independent 6 star energy rating | D62: Included
B63: SERVICE CONNECTIONS
B64: Sewer run and connection fees to 700m2 block | D64: Included
B65: Water run and connection fees to 6m front setback | D65: Included
B66: Stormwater connection to 6m front setback | D66: Included
B67: Electricity run to 6m front setback (does not include connection fee) | D67: Included
B68: Gas service is to be supplied by the retailer
B69: FOUNDATIONS
B70: Site fall up to 200mm | D70: Included
B71: MD class concrete slab (floor height at least 250mm - there is no allowance for piers) | D71: Included
B72: Concrete pump | D72: Included
...

Sheet Travel Working
A1: Draftee travel per km | B1: =+((65+65)/100) -> 1.3
A2: Truck cost per km | B2: 1.65 | F2: 23/06/25 - Add $50 for TV Antenna Install
A3: Carpenter travel per km | B3: 1.65
A4: Supervisor tavel per km | B4: 1.65
A5: Concrete pump travel | B5: 4
A6: Stone benchtops | B6: 6
B7: Kms | C7: Cost per km return | D7: Bunnings delivery | E7: Drafting inspwction travel | F7: Temp fencing travel | G7: Skip run | H7: site screpe travel | I7: Crusher dust | K7: Concrete supply | M7: Pump travel | P7: Bricks delivery | R7: Brick sand | T7: Stone travel | W7: Supervisor travel | X7: Solar pnel travel
A8: SHEPPARTON | B8: 20 | C8: =+B2*2 -> 3.3 | D8: 45.45 | E8: =+C8*B8 -> 66 | F8: =+C8*B8 -> 66 | G8: =+C8*B8*6 -> 396 | H8: =+C8*B8 -> 66 | I8: 51 | J8: =+I8*35 -> 1785 | K8: 210 | L8: =+K8*60 -> 12600 | M8: =+B5 -> 4 | N8: =+B8-80 -> -60 | O8: =IF((N8>0),(N8*M8*2),) -> 0 | P8: 55 | Q8: =+P8*8 -> 440 | R8: 44 | S8: =+R8*9 -> 396 | T8: =+B6 -> 6 | V8: =+B4 -> 1.65 | W8: =+V8*2*B8*10 -> 660 | AF8: =+A8 -> SHEPPARTON
A9: ALEXANDRA | B9: 120 | C9: =+C8 -> 3.3 | D9: 150 | E9: =+C9*B9 -> 396 | F9: =+C9*B9 -> 396 | G9: =+C9*B9*6 -> 2376 | H9: =+C9*B9 -> 396 | I9: 85 | J9: =+I9*35 -> 2975 | K9: 287 | L9: =+K9*60 -> 17220 | M9: =+M8 -> 4 | N9: =+B9-80 -> 40 | O9: =IF((N9>0),(N9*M9*2),) -> 320 | P9: 65 | Q9: =+P9*8 -> 520 | R9: 80 | S9: =+R9*9 -> 720 | T9: =+T8 -> 6 | U9: =+IF(((B9-80)>0),((B9-80)*T9),0) -> 240 | V9: =+V8 -> 1.65 | W9: =+V9*2*B9*10 -> 3960 | X9: 2 | Y9: =+X9*B9 -> 240 | AF9: =+A9 -> ALEXANDRA | AG9: =+C95-B95 -> 30199.75 | AH9: =+CEILING(AG9*1.36,10) -> 41080
A10: AVENEL | B10: 71 | C10: =+C9 -> 3.3 | D10: 110 | E10: =+C10*B10 -> 234.3 | F10: =+C10*B10 -> 234.3 | G10: =+C10*B10*6 -> 1405.8 | H10: =+C10*B10 -> 234.3 | I10: 65 | J10: =+I10*35 -> 2275 | K10: 210 | L10: =+K10*60 -> 12600 | M10: =+M9 -> 4 | N10: =+B10-80 -> -9 | O10: =IF((N10>0),(N10*M10*2),) -> 0 | P10: 55 | Q10: =+P10*8 -> 440 | R10: 56 | S10: =+R10*9 -> 504 | T10: =+T9 -> 6 | U10: =+IF(((B10-80)>0),((B10-80)*T10),0) -> 0 | V10: =+V9 -> 1.65 | W10: =+V10*2*B10*10 -> 2343 | X10: 2 | Y10: =+X10*B10 -> 142 | AF10: =+A10 -> AVENEL | AG10: =+D95-B95 -> 11128.05 | AH10: =+CEILING(AG10*1.36,10) -> 15140
A11: BENALLA | B11: 62 | C11: =+C10 -> 3.3 | D11: 70 | E11: =+C11*B11 -> 204.6 | F11: =+C11*B11 -> 204.6 | G11: =+C11*B11*6 -> 1227.6 | H11: =+C11*B11 -> 204.6 | I11: 65 | J11: =+I11*35 -> 2275 | K11: 235 | L11: =+K11*60 -> 14100 | M11: =+M10 -> 4 | N11: =+B11-80 -> -18 | O11: =IF((N11>0),(N11*M11*2),) -> 0 | P11: 55 | Q11: =+P11*8 -> 440 | R11: 54 | S11: =+R11*9 -> 486 | T11: =+T10 -> 6 | U11: =+IF(((B11-80)>0),((B11-80)*T11),0) -> 0 | V11: =+V10 -> 1.65 | W11: =+V11*2*B11*10 -> 2046 | X11: 2 | Y11: =+X11*B11 -> 124 | AF11: =+A11 -> BENALLA | AG11: =+E95-B95 -> 10508.35 | AH11: =+CEILING(AG11*1.36,10) -> 14300
A12: COBRAM | B12: 71 | C12: =+C11 -> 3.3 | D12: 70 | E12: =+C12*B12 -> 234.3 | F12: =+C12*B12 -> 234.3 | G12: =+C12*B12*6 -> 1405.8 | H12: =+C12*B12 -> 234.3 | I12: 65 | J12: =+I12*35 -> 2275 | K12: 220 | L12: =+K12*60 -> 13200 | M12: =+M11 -> 4 | N12: =+B12-80 -> -9 | O12: =IF((N12>0),(N12*M12*2),) -> 0 | P12: 70 | Q12: =+P12*8 -> 560 | R12: 54 | S12: =+R12*9 -> 486 | T12: =+T11 -> 6 | U12: =+IF(((B12-80)>0),((B12-80)*T12),0) -> 0 | V12: =+V11 -> 1.65 | W12: =+V12*2*B12*10 -> 2343 | X12: 2 | Y12: =+X12*B12 -> 142 | AF12: =+A12 -> COBRAM | AG12: =+F95-B95 -> 10430.05 | AH12: =+CEILING(AG12*1.36,10) -> 14190
A13: COHUNA | B13: 135 | C13: =+C12 -> 3.3 | D13: =+D9 -> 150 | E13: =+C13*B13 -> 445.5 | F13: =+C13*B13 -> 445.5 | G13: =+C13*B13*6 -> 2673 | H13: =+C13*B13 -> 445.5 | I13: 85 | J13: =+I13*35 -> 2975 | K13: 345 | L13: =+K13*60 -> 20700 | M13: =+M12 -> 4 | N13: =+B13-80 -> 55 | O13: =IF((N13>0),(N13*M13*2),) -> 440 | P13: 80 | Q13: =+P13*8 -> 640 | R13: 80 | S13: =+R13*9 -> 720 | T13: =+T12 -> 6 | U13: =+IF(((B13-80)>0),((B13-80)*T13),0) -> 330 | V13: =+V12 -> 1.65 | W13: =+V13*2*B13*10 -> 4455 | X13: 2 | Y13: =+X13*B13 -> 270 | AF13: =+A13 -> COHUNA | AG13: =+G95-B95 -> 34627.25 | AH13: =+CEILING(AG13*1.36,10) -> 47100
A14: DENILIQUIN | B14: 137 | C14: =+C13 -> 3.3 | D14: =+D13 -> 150 | E14: =+C14*B14 -> 452.1 | F14: =+C14*B14 -> 452.1 | G14: =+C14*B14*6 -> 2712.6 | H14: =+C14*B14 -> 452.1 | I14: 85 | J14: =+I14*35 -> 2975 | K14: 358 | L14: =+K14*60 -> 21480 | M14: =+M13 -> 4 | N14: =+B14-80 -> 57 | O14: =IF((N14>0),(N14*M14*2),) -> 456 | P14: 80 | Q14: =+P14*8 -> 640 | R14: 80 | S14: =+R14*9 -> 720 | T14: =+T13 -> 6 | U14: =+IF(((B14-80)>0),((B14-80)*T14),0) -> 342 | V14: =+V13 -> 1.65 | W14: =+V14*2*B14*10 -> 4521 | X14: 2 | Y14: =+X14*B14 -> 274 | AF14: =+A14 -> DENILIQUIN | AG14: =+H95-B95 -> 36237.85 | AH14: =+CEILING(AG14*1.36,10)+D108 -> 57490
A15: ECHUCA | B15: 71 | C15: =+C14 -> 3.3 | D15: 80 | E15: =+C15*B15 -> 234.3 | F15: =+C15*B15 -> 234.3 | G15: =+C15*B15*6 -> 1405.8 | H15: =+C15*B15 -> 234.3 | I15: 63 | J15: =+I15*35 -> 2205 | K15: 230 | L15: =+K15*60 -> 13800 | M15: =+M14 -> 4 | N15: =+B15-80 -> -9 | O15: =IF((N15>0),(N15*M15*2),) -> 0 | P15: 60 | Q15: =+P15*8 -> 480 | R15: 55 | S15: =+R15*9 -> 495 | T15: =+T14 -> 6 | U15: =+IF(((B15-80)>0),((B15-80)*T15),0) -> 0 | V15: =+V14 -> 1.65 | W15: =+V15*2*B15*10 -> 2343 | X15: 2 | Y15: =+X15*B15 -> 142 | AF15: =+A15 -> ECHUCA | AG15: =+I95-B95 -> 10112.05 | AH15: =+CEILING(AG15*1.36,10) -> 13760
A16: EUROA | B16: 49 | C16: =+C15 -> 3.3 | D16: 90 | E16: =+C16*B16 -> 161.7 | F16: =+C16*B16 -> 161.7 | G16: =+C16*B16*6 -> 970.2 | H16: =+C16*B16 -> 161.7 | I16: 63 | J16: =+I16*35 -> 2205 | K16: 257 | L16: =+K16*60 -> 15420 | M16: =+M15 -> 4 | N16: =+B16-80 -> -31 | O16: =IF((N16>0),(N16*M16*2),) -> 0 | P16: 55 | Q16: =+P16*8 -> 440 | R16: 52 | S16: =+R16*9 -> 468 | T16: =+T15 -> 6 | U16: =+IF(((B16-80)>0),((B16-80)*T16),0) -> 0 | V16: =+V15 -> 1.65 | W16: =+V16*2*B16*10 -> 1617 | X16: 2 | Y16: =+X16*B16 -> 98 | AF16: =+A16 -> EUROA | AG16: =+J95-B95 -> 8150.45 | AH16: =+CEILING(AG16*1.36,10) -> 11090
A17: FINLEY | B17: 101 | C17: =+C16 -> 3.3 | D17: =+D13 -> 150 | E17: =+C17*B17 -> 333.3 | F17: =+C17*B17 -> 333.3 | G17: =+C17*B17*6 -> 1999.8 | H17: =+C17*B17 -> 333.3 | I17: 85 | J17: =+I17*35 -> 2975 | K17: 247 | L17: =+K17*60 -> 14820 | M17: =+M16 -> 4 | N17: =+B17-80 -> 21 | O17: =IF((N17>0),(N17*M17*2),) -> 168 | P17: 80 | Q17: =+P17*8 -> 640 | R17: 80 | S17: =+R17*9 -> 720 | T17: =+T16 -> 6 | U17: =+IF(((B17-80)>0),((B17-80)*T17),0) -> 126 | V17: =+V16 -> 1.65 | W17: =+V17*2*B17*10 -> 3333 | X17: 2 | Y17: =+X17*B17 -> 202 | AF17: =+A17 -> FINLEY | AG17: =+K95-B95 -> 23952.05 | AH17: =+CEILING(AG17*1.36,10)+D108 -> 40780
A18: KATANDRA | B18: 29 | C18: =+C17 -> 3.3 | D18: =+D10 -> 110 | E18: =+C18*B18 -> 95.7 | F18: =+C18*B18 -> 95.7 | G18: =+C18*B18*6 -> 574.2 | H18: =+C18*B18 -> 95.7 | I18: 65 | J18: =+I18*35 -> 2275 | K18: 223 | L18: =+K18*60 -> 13380 | M18: =+M17 -> 4 | N18: =+B18-80 -> -51 | O18: =IF((N18>0),(N18*M18*2),) -> 0 | P18: 65 | Q18: =+P18*8 -> 520 | R18: 60 | S18: =+R18*9 -> 540 | T18: =+T17 -> 6 | U18: =+IF(((B18-80)>0),((B18-80)*T18),0) -> 0 | V18: =+V17 -> 1.65 | W18: =+V18*2*B18*10 -> 957 | X18: 2 | Y18: =+X18*B18 -> 58 | AF18: =+A18 -> KATANDRA | AG18: =+L95-B95 -> 5731.45 | AH18: =+CEILING(AG18*1.36,10) -> 7800
A19: KOONDROOK | B19: 158 | C19: =+C18 -> 3.3 | D19: =+D14 -> 150 | E19: =+C19*B19 -> 521.4 | F19: =+C19*B19 -> 521.4 | G19: =+C19*B19*6 -> 3128.4 | H19: =+C19*B19 -> 521.4 | I19: 85 | J19: =+I19*35 -> 2975 | K19: 345 | L19: =+K19*60 -> 20700 | M19: =+M18 -> 4 | N19: =+B19-80 -> 78 | O19: =IF((N19>0),(N19*M19*2),) -> 624 | P19: 80 | Q19: =+P19*8 -> 640 | R19: 80 | S19: =+R19*9 -> 720 | T19: =+T18 -> 6 | U19: =+IF(((B19-80)>0),((B19-80)*T19),0) -> 468 | V19: =+V18 -> 1.65 | W19: =+V19*2*B19*10 -> 5214 | X19: 2 | Y19: =+X19*B19 -> 316 | AF19: =+A19 -> KOONDROOK | AG19: =+M95-B95 -> 37089.15 | AH19: =+CEILING(AG19*1.36,10) -> 50450
A20: KYABRAM | B20: 37 | C20: =+C19 -> 3.3 | D20: 50 | E20: =+C20*B20 -> 122.1 | F20: =+C20*B20 -> 122.1 | G20: =+C20*B20*6 -> 732.6 | H20: =+C20*B20 -> 122.1 | I20: 63 | J20: =+I20*35 -> 2205 | K20: 230 | L20: =+K20*60 -> 13800 | M20: =+M19 -> 4 | N20: =+B20-80 -> -43 | O20: =IF((N20>0),(N20*M20*2),) -> 0 | P20: 75 | Q20: =+P20*8 -> 600 | R20: 52 | S20: =+R20*9 -> 468 | T20: =+T19 -> 6 | U20: =+IF(((B20-80)>0),((B20-80)*T20),0) -> 0 | V20: =+V19 -> 1.65 | W20: =+V20*2*B20*10 -> 1221 | X20: 2 | Y20: =+X20*B20 -> 74 | AF20: =+A20 -> KYABRAM | AG20: =+N95-B95 -> 4414.85 | AH20: =+CEILING(AG20*1.36,10) -> 6010
A21: MANSFIELD | B21: 125 | C21: =+C20 -> 3.3 | D21: 110 | E21: =+C21*B21 -> 412.5 | F21: =+C21*B21 -> 412.5 | G21: =+C21*B21*6 -> 2475 | H21: =+C21*B21 -> 412.5 | I21: 85 | J21: =+I21*35 -> 2975 | K21: 279 | L21: =+K21*60 -> 16740 | M21: =+M20 -> 4 | N21: =+B21-80 -> 45 | O21: =IF((N21>0),(N21*M21*2),) -> 360 | P21: 70 | Q21: =+P21*8 -> 560 | R21: 80 | S21: =+R21*9 -> 720 | T21: =+T20 -> 6 | U21: =+IF(((B21-80)>0),((B21-80)*T21),0) -> 270 | V21: =+V20 -> 1.65 | W21: =+V21*2*B21*10 -> 4125 | X21: 2 | Y21: =+X21*B21 -> 250 | AF21: =+A21 -> MANSFIELD | AG21: =+O95-B95 -> 31674.25 | AH21: =+CEILING(AG21*1.36,10) -> 43080
A22: MATHOURA | B22: 103 | C22: =+C21 -> 3.3 | D22: =+D19 -> 150 | E22: =+C22*B22 -> 339.9 | F22: =+C22*B22 -> 339.9 | G22: =+C22*B22*6 -> 2039.4 | H22: =+C22*B22 -> 339.9 | I22: 85 | J22: =+I22*35 -> 2975 | K22: =+K14 -> 358 | L22: =+K22*60 -> 21480 | M22: =+M21 -> 4 | N22: =+B22-80 -> 23 | O22: =IF((N22>0),(N22*M22*2),) -> 184 | P22: 80 | Q22: =+P22*8 -> 640 | R22: 80 | S22: =+R22*9 -> 720 | T22: =+T21 -> 6 | U22: =+IF(((B22-80)>0),((B22-80)*T22),0) -> 138 | V22: =+V21 -> 1.65 | W22: =+V22*2*B22*10 -> 3399 | X22: 2 | Y22: =+X22*B22 -> 206 | AF22: =+A22 -> MATHOURA | AG22: =+P95-B95 -> 31664.65 | AH22: =+CEILING(AG22*1.36,10)+D108 -> 51270
A23: MURCHISON | B23: 43 | C23: =+C22 -> 3.3 | D23: 90 | E23: =+C23*B23 -> 141.9 | F23: =+C23*B23 -> 141.9 | G23: =+C23*B23*6 -> 851.4 | H23: =+C23*B23 -> 141.9 | I23: 65 | J23: =+I23*35 -> 2275 | K23: 218 | L23: =+K23*60 -> 13080 | M23: =+M22 -> 4 | N23: =+B23-80 -> -37 | O23: =IF((N23>0),(N23*M23*2),) -> 0 | P23: 55 | Q23: =+P23*8 -> 440 | R23: 52 | S23: =+R23*9 -> 468 | T23: =+T22 -> 6 | U23: =+IF(((B23-80)>0),((B23-80)*T23),0) -> 0 | V23: =+V22 -> 1.65 | W23: =+V23*2*B23*10 -> 1419 | X23: 2 | Y23: =+X23*B23 -> 86 | AF23: =+A23 -> MURCHISON | AG23: =+Q95-B95 -> 5212.65 | AH23: =+CEILING(AG23*1.36,10) -> 7090
A24: NAGAMBIE | B24: 60 | C24: =+C23 -> 3.3 | D24: 70 | E24: =+C24*B24 -> 198 | F24: =+C24*B24 -> 198 | G24: =+C24*B24*6 -> 1188 | H24: =+C24*B24 -> 198 | I24: 65 | J24: =+I24*35 -> 2275 | K24: 210 | L24: =+K24*60 -> 12600 | M24: =+M23 -> 4 | N24: =+B24-80 -> -20 | O24: =IF((N24>0),(N24*M24*2),) -> 0 | P24: 50 | Q24: =+P24*8 -> 400 | R24: 54 | S24: =+R24*9 -> 486 | T24: =+T23 -> 6 | U24: =+IF(((B24-80)>0),((B24-80)*T24),0) -> 0 | V24: =+V23 -> 1.65 | W24: =+V24*2*B24*10 -> 1980 | X24: 2 | Y24: =+X24*B24 -> 120 | AF24: =+A24 -> NAGAMBIE | AG24: =+R95-B95 -> 7455.75 | AH24: =+CEILING(AG24*1.36,10) -> 10140
A25: NATHALIA | B25: 40 | C25: =+C24 -> 3.3 | D25: 70 | E25: =+C25*B25 -> 132 | F25: =+C25*B25 -> 132 | G25: =+C25*B25*6 -> 792 | H25: =+C25*B25 -> 132 | I25: 63 | J25: =+I25*35 -> 2205 | K25: 232 | L25: =+K25*60 -> 13920 | M25: =+M24 -> 4 | N25: =+B25-80 -> -40 | O25: =IF((N25>0),(N25*M25*2),) -> 0 | P25: 65 | Q25: =+P25*8 -> 520 | R25: 52 | S25: =+R25*9 -> 468 | T25: =+T24 -> 6 | U25: =+IF(((B25-80)>0),((B25-80)*T25),0) -> 0 | V25: =+V24 -> 1.65 | W25: =+V25*2*B25*10 -> 1320 | X25: 2 | Y25: =+X25*B25 -> 80 | AF25: =+A25 -> NATHALIA | AG25: =+S95-B95 -> 5868.75 | AH25: =+CEILING(AG25*1.36,10) -> 7990
A26: NUMURKAH | B26: 35 | C26: =+C25 -> 3.3 | D26: 60 | E26: =+C26*B26 -> 115.5 | F26: =+C26*B26 -> 115.5 | G26: =+C26*B26*6 -> 693 | H26: =+C26*B26 -> 115.5 | I26: 51 | J26: =+I26*35 -> 1785 | K26: 220 | L26: =+K26*60 -> 13200 | M26: =+M25 -> 4 | N26: =+B26-80 -> -45 | O26: =IF((N26>0),(N26*M26*2),) -> 0 | P26: 55 | Q26: =+P26*8 -> 440 | R26: 44 | S26: =+R26*9 -> 396 | T26: =+T25 -> 6 | U26: =+IF(((B26-80)>0),((B26-80)*T26),0) -> 0 | V26: =+V25 -> 1.65 | W26: =+V26*2*B26*10 -> 1155 | X26: 2 | Y26: =+X26*B26 -> 70 | AF26: =+A26 -> NUMURKAH | AG26: =+T95-B95 -> 3435.25 | AH26: =+CEILING(AG26*1.36,10) -> 4680
A27: ROCHESTER | B27: 70 | C27: =+C26 -> 3.3 | D27: 90 | E27: =+C27*B27 -> 231 | F27: =+C27*B27 -> 231 | G27: =+C27*B27*6 -> 1386 | H27: =+C27*B27 -> 231 | I27: 65 | J27: =+I27*35 -> 2275 | K27: 256 | L27: =+K27*60 -> 15360 | M27: =+M26 -> 4 | N27: =+B27-80 -> -10 | O27: =IF((N27>0),(N27*M27*2),) -> 0 | P27: 75 | Q27: =+P27*8 -> 600 | R27: 54 | S27: =+R27*9 -> 486 | T27: =+T26 -> 6 | U27: =+IF(((B27-80)>0),((B27-80)*T27),0) -> 0 | V27: =+V26 -> 1.65 | W27: =+V27*2*B27*10 -> 2310 | X27: 2 | Y27: =+X27*B27 -> 140 | AF27: =+A27 -> ROCHESTER | AG27: =+U95-B95 -> 11838.75 | AH27: =+CEILING(AG27*1.36,10) -> 16110
A28: RUSHWORTH | B28: 48 | C28: =+C27 -> 3.3 | D28: 90 | E28: =+C28*B28 -> 158.4 | F28: =+C28*B28 -> 158.4 | G28: =+C28*B28*6 -> 950.4 | H28: =+C28*B28 -> 158.4 | I28: 65 | J28: =+I28*35 -> 2275 | K28: 242 | L28: =+K28*60 -> 14520 | M28: =+M27 -> 4 | N28: =+B28-80 -> -32 | O28: =IF((N28>0),(N28*M28*2),) -> 0 | P28: 80 | Q28: =+P28*8 -> 640 | R28: 52 | S28: =+R28*9 -> 468 | T28: =+T27 -> 6 | U28: =+IF(((B28-80)>0),((B28-80)*T28),0) -> 0 | V28: =+V27 -> 1.65 | W28: =+V28*2*B28*10 -> 1584 | X28: 2 | Y28: =+X28*B28 -> 96 | AF28: =+A28 -> RUSHWORTH | AG28: =+V95-B95 -> 6749.15 | AH28: =+CEILING(AG28*1.36,10) -> 9180
A29: SEYMOUR | B29: 86 | C29: =+C28 -> 3.3 | D29: 110 | E29: =+C29*B29 -> 283.8 | F29: =+C29*B29 -> 283.8 | G29: =+C29*B29*6 -> 1702.8 | H29: =+C29*B29 -> 283.8 | I29: 65 | J29: =+I29*35 -> 2275 | K29: 220 | L29: =+K29*60 -> 13200 | M29: =+M28 -> 4 | N29: =+B29-80 -> 6 | O29: =IF((N29>0),(N29*M29*2),) -> 48 | P29: 55 | Q29: =+P29*8 -> 440 | R29: 54 | S29: =+R29*9 -> 486 | T29: =+T28 -> 6 | U29: =+IF(((B29-80)>0),((B29-80)*T29),0) -> 36 | V29: =+V28 -> 1.65 | W29: =+V29*2*B29*10 -> 2838 | X29: 2 | Y29: =+X29*B29 -> 172 | AF29: =+A29 -> SEYMOUR | AG29: =+W95-B95 -> 11918.55 | AH29: =+CEILING(AG29*1.36,10) -> 16210
A30: STANHOPE | B30: 42 | C30: =+C29 -> 3.3 | D30: 60 | E30: =+C30*B30 -> 138.6 | F30: =+C30*B30 -> 138.6 | G30: =+C30*B30*6 -> 831.6 | H30: =+C30*B30 -> 138.6 | I30: 63 | J30: =+I30*35 -> 2205 | K30: 232 | L30: =+K30*60 -> 13920 | M30: =+M29 -> 4 | N30: =+B30-80 -> -38 | O30: =IF((N30>0),(N30*M30*2),) -> 0 | P30: 80 | Q30: =+P30*8 -> 640 | R30: 52 | S30: =+R30*9 -> 468 | T30: =+T29 -> 6 | U30: =+IF(((B30-80)>0),((B30-80)*T30),0) -> 0 | V30: =+V29 -> 1.65 | W30: =+V30*2*B30*10 -> 1386 | X30: 2 | Y30: =+X30*B30 -> 84 | AF30: =+A30 -> STANHOPE | AG30: =+X95-B95 -> 5751.35 | AH30: =+CEILING(AG30*1.36,10) -> 7830
A31: STRATHMERTON | B31: 56 | C31: =+C30 -> 3.3 | D31: 70 | E31: =+C31*B31 -> 184.8 | F31: =+C31*B31 -> 184.8 | G31: =+C31*B31*6 -> 1108.8 | H31: =+C31*B31 -> 184.8 | I31: 65 | J31: =+I31*35 -> 2275 | K31: 216 | L31: =+K31*60 -> 12960 | M31: =+M30 -> 4 | N31: =+B31-80 -> -24 | O31: =IF((N31>0),(N31*M31*2),) -> 0 | P31: 70 | Q31: =+P31*8 -> 560 | R31: 52 | S31: =+R31*9 -> 468 | T31: =+T30 -> 6 | U31: =+IF(((B31-80)>0),((B31-80)*T31),0) -> 0 | V31: =+V30 -> 1.65 | W31: =+V31*2*B31*10 -> 1848 | X31: 2 | Y31: =+X31*B31 -> 112 | AF31: =+A31 -> STRATHMERTON | AG31: =+Y95-B95 -> 7130.55 | AH31: =+CEILING(AG31*1.36,10) -> 9700
A32: TATURA | B32: 20 | C32: =+C31 -> 3.3 | D32: =+D8 -> 45.45 | E32: =+C32*B32 -> 66 | F32: =+C32*B32 -> 66 | G32: =+C32*B32*6 -> 396 | H32: =+C32*B32 -> 66 | I32: 51 | J32: =+I32*35 -> 1785 | K32: 210 | L32: =+K32*60 -> 12600 | M32: =+M31 -> 4 | N32: =+B32-80 -> -60 | O32: =IF((N32>0),(N32*M32*2),) -> 0 | P32: 60 | Q32: =+P32*8 -> 480 | R32: 44 | S32: =+R32*9 -> 396 | T32: =+T31 -> 6 | U32: =+IF(((B32-80)>0),((B32-80)*T32),0) -> 0 | V32: =+V31 -> 1.65 | W32: =+V32*2*B32*10 -> 660 | X32: 2 | AF32: =+A32 -> TATURA | AG32: =+Z95-B95 -> 890 | AH32: =+CEILING(AG32*1.36,10) -> 1220
A33: TONGALA | B33: 57 | C33: =+C32 -> 3.3 | D33: 80 | E33: =+C33*B33 -> 188.1 | F33: =+C33*B33 -> 188.1 | G33: =+C33*B33*6 -> 1128.6 | H33: =+C33*B33 -> 188.1 | I33: 65 | J33: =+I33*35 -> 2275 | K33: 230 | L33: =+K33*60 -> 13800 | M33: =+M32 -> 4 | N33: =+B33-80 -> -23 | O33: =IF((N33>0),(N33*M33*2),) -> 0 | P33: 85 | Q33: =+P33*8 -> 680 | R33: 52 | S33: =+R33*9 -> 468 | T33: =+T32 -> 6 | U33: =+IF(((B33-80)>0),((B33-80)*T33),0) -> 0 | V33: =+V32 -> 1.65 | W33: =+V33*2*B33*10 -> 1881 | X33: 2 | Y33: =+X33*B33 -> 114 | AF33: =+A33 -> TONGALA | AG33: =+AA95-B95 -> 7561.85 | AH33: =+CEILING(AG33*1.36,10) -> 10290
A34: TUNGAMAH | B34: 59 | C34: =+C33 -> 3.3 | D34: =+D10 -> 110 | E34: =+C34*B34 -> 194.7 | F34: =+C34*B34 -> 194.7 | G34: =+C34*B34*6 -> 1168.2 | H34: =+C34*B34 -> 194.7 | I34: 65 | J34: =+I34*35 -> 2275 | K34: 240 | L34: =+K34*60 -> 14400 | M34: =+M33 -> 4 | N34: =+B34-80 -> -21 | O34: =IF((N34>0),(N34*M34*2),) -> 0 | P34: 70 | Q34: =+P34*8 -> 560 | R34: 65 | S34: =+R34*9 -> 585 | T34: =+T33 -> 6 | U34: =+IF(((B34-80)>0),((B34-80)*T34),0) -> 0 | V34: =+V33 -> 1.65 | W34: =+V34*2*B34*10 -> 1947 | X34: 2 | Y34: =+X34*B34 -> 118 | AF34: =+A34 -> TUNGAMAH | AG34: =+AB95-B95 -> 11173.45 | AH34: =+CEILING(AG34*1.36,10) -> 15200
A35: YARRAWONGA | B35: 78 | C35: =+C34 -> 3.3 | D35: 80 | E35: =+C35*B35 -> 257.4 | F35: =+C35*B35 -> 257.4 | G35: =+C35*B35*6 -> 1544.4 | H35: =+C35*B35 -> 257.4 | I35: 65 | J35: =+I35*35 -> 2275 | K35: 220 | L35: =+K35*60 -> 13200 | M35: =+M34 -> 4 | N35: =+B35-80 -> -2 | O35: =IF((N35>0),(N35*M35*2),) -> 0 | P35: 65 | Q35: =+P35*8 -> 520 | R35: 54 | S35: =+R35*9 -> 486 | T35: =+T34 -> 6 | U35: =+IF(((B35-80)>0),((B35-80)*T35),0) -> 0 | V35: =+V34 -> 1.65 | W35: =+V35*2*B35*10 -> 2574 | X35: 2 | Y35: =+X35*B35 -> 156 | AF35: =+A35 -> YARRAWONGA | AG35: =+AC95-B95 -> 11539.15 | AH35: =+CEILING(AG35*1.36,10) -> 15700
A36: YEA | B36: 119 | C36: =+C35 -> 3.3 | D36: =+D22 -> 150 | E36: =+C36*B36 -> 392.7 | F36: =+C36*B36 -> 392.7 | G36: =(+VALUE(B36))*1.65 -> 196.35 | H36: =+C36*B36 -> 392.7 | I36: 85 | J36: =+I36*35 -> 2975 | K36: 295 | L36: =+K36*60 -> 17700 | M36: =+M35 -> 4 | N36: =+B36-80 -> 39 | O36: =IF((N36>0),(N36*M36*2),) -> 312 | P36: 80 | Q36: =+P36*8 -> 640 | R36: 80 | S36: =+R36*9 -> 720 | T36: =+T35 -> 6 | U36: =+IF(((B36-80)>0),((B36-80)*T36),0) -> 234 | V36: =+V35 -> 1.65 | W36: =+V36*2*B36*10 -> 3927 | X36: 2 | Y36: =+X36*B36 -> 238 | AF36: =+A36 -> YEA | AG36: =+AD95-B95 -> 28472.6 | AH36: =+CEILING(AG36*1.36,10) -> 38730
B38: 3630 | C38: 3714 | D38: 3664 | E38: 3671 | F38: 3644 | G38: 3568 | H38: 2710 | I38: 3564 | J38: 3666 | K38: 2713 | L38: 3634 | M38: 3580 | N38: 3620 | O38: 3722 | P38: 2710 | Q38: 3610 | R38: 3608 | S38: 3638 | T38: 3636 | U38: 3561 | V38: 3612 | W38: 3660 | X38: 3623 | Y38: 3641 | Z38: 3616 | AA38: 3621 | AB38: 3728 | AC38: 3730 | AD38: 3717
B39: SHEPPARTON | C39: ALEXANDRA | D39: AVENEL | E39: BENALLA | F39: COBRAM | G39: COHUNA | H39: DENILIQUIN | I39: ECHUCA | J39: EUROA | K39: FINLEY | L39: KATANDRA | M39: KOONDROOK | N39: KYABRAM | O39: MANSFIELD | P39: MATHOURA | Q39: MURCHISON | R39: NAGAMBIE | S39: NATHALIA | T39: NUMURKAH | U39: ROCHESTER | V39: RUSHWORTH | W39: SEYMOUR | X39: STANHOPE | Y39: STRATHMERTON | Z39: TATURA | AA39: TONGALA | AB39: TUNGAMAH | AC39: YARRAWONGA | AD39: YEA
A40: Km | C40: 120km | D40: 71km | E40: 62km | F40: 71km | G40: 135km | H40: 137KM | I40: 71km | J40: 49km | K40: 101km | L40: 29km | M40: 158km | N40: 37km | O40: 125km | P40: 103km | Q40: 43km | R40: 60km | S40: 40km | T40: 35km | U40: 70km | V40: 48km | W40: 86km | X40: 42km | Y40: 56km | Z40: 20km | AA40: 57km | AB40: 59km | AC40: 78km | AD40: 119km
A41: Bunnings delivery - (205, 350, 385, 395) Added extra delivery Load 5 on 545 Fix materials | B41: =+D8*5 -> 227.25 | C41: =+D9*5 -> 750 | D41: =+D10*5 -> 550 | E41: =+D11*5 -> 350 | F41: =+D12*5 -> 350 | G41: =+D13*5 -> 750 | H41: =+D14*5 -> 750 | I41: =+D15*5 -> 400 | J41: =+D16*5 -> 450 | K41: =+D17*5 -> 750 | L41: =+D18*5 -> 550 | M41: =+D19*5 -> 750 | N41: =+D20*5 -> 250 | O41: =+D21*5 -> 550 | P41: =+D22*5 -> 750 | Q41: =+D23*5 -> 450 | R41: =+D24*5 -> 350 | S41: =+D25*5 -> 350 | T41: =+D26*5 -> 300 | U41: =+D27*5 -> 450 | V41: =+D28*5 -> 450 | W41: =+D29*5 -> 550 | X41: =+D30*5 -> 300 | Y41: =+D31*5 -> 350 | Z41: =+D32*5 -> 227.25 | AA41: =+D33*5 -> 400 | AB41: =+D34*5 -> 550 | AC41: =+D35*5 -> 400 | AD41: =+D36*5 -> 750
...

Sheet Estimator
B2: Base House Plan | C2: Price per sqm | D2: Tiles | E2: Carpets | H2: Pick the closest floor plan and add the items | N2: This sheet is good for adding area, NOT deleting
B3: =+'Fast Key'!A13 -> Byron 19 | C3: =+'Fast Key'!BO13 -> 0 | D3: =+Shepparton!#REF! -> #REF! | E3: =+Shepparton!#REF! -> #REF!
B4: =+'Fast Key'!A14 -> Byron 22A | C4: =+'Fast Key'!BO14 -> 0 | D4: =+Shepparton!#REF! -> #REF! | E4: =+Shepparton!#REF! -> #REF!
B5: =+'Fast Key'!A15 -> Byron 22B | C5: =+'Fast Key'!BO15 -> 0 | D5: =+Shepparton!#REF! -> #REF! | E5: =+Shepparton!#REF! -> #REF!
B6: =+'Fast Key'!A16 -> Ashwood 17 | C6: =+'Fast Key'!BO16 -> 0 | D6: =+Shepparton!#REF! -> #REF! | E6: =+Shepparton!#REF! -> #REF!
B7: =+'Fast Key'!A17 -> Ashwood 20 | C7: =+'Fast Key'!BO17 -> 0 | D7: =+Shepparton!#REF! -> #REF! | E7: =+Shepparton!#REF! -> #REF!
B8: =+'Fast Key'!A18 -> Malvern 20 | C8: =+'Fast Key'!BO18 -> 0 | D8: =+Shepparton!#REF! -> #REF! | E8: =+Shepparton!#REF! -> #REF!
B9: =+'Fast Key'!A19 -> Malvern 23 | C9: =+'Fast Key'!BO19 -> 0 | D9: =+Shepparton!#REF! -> #REF! | E9: =+Shepparton!#REF! -> #REF!
B10: =+'Fast Key'!A21 -> 0 | C10: =+'Fast Key'!BO21 -> 0 | D10: =+Shepparton!#REF! -> #REF! | E10: =+Shepparton!#REF! -> #REF!
B11: =+'Fast Key'!A22 -> 0 | C11: =+'Fast Key'!BO22 -> 0 | D11: =+Shepparton!#REF! -> #REF! | E11: =+Shepparton!#REF! -> #REF!
B12: =+'Fast Key'!A24 -> 0 | C12: =+'Fast Key'!BO24 -> 0 | D12: =+Shepparton!#REF! -> #REF! | E12: =+Shepparton!#REF! -> #REF!
B13: =+'Fast Key'!A26 -> 0 | C13: =+'Fast Key'!BO26 -> 0 | D13: =+Shepparton!#REF! -> #REF! | E13: =+Shepparton!#REF! -> #REF!
B14: =+'Fast Key'!A27 -> 0 | C14: =+'Fast Key'!BO27 -> 0 | D14: =+Shepparton!#REF! -> #REF! | E14: =+Shepparton!#REF! -> #REF!
B15: =+'Fast Key'!A28 -> 0 | C15: =+'Fast Key'!BO28 -> 0 | D15: =+Shepparton!#REF! -> #REF! | E15: =+Shepparton!#REF! -> #REF!
B16: =+'Fast Key'!A29 -> 0 | C16: =+'Fast Key'!BO29 -> 0 | D16: =+Shepparton!#REF! -> #REF! | E16: =+Shepparton!#REF! -> #REF!
B17: =+'Fast Key'!A30 -> 0 | C17: =+'Fast Key'!BO30 -> 0 | D17: =+Shepparton!#REF! -> #REF! | E17: =+Shepparton!#REF! -> #REF!
B18: =+'Fast Key'!A31 -> 0 | C18: =+'Fast Key'!BO31 -> 0 | D18: =+Shepparton!#REF! -> #REF! | E18: =+Shepparton!#REF! -> #REF!
B19: =+'Fast Key'!A34 -> 0 | C19: =+'Fast Key'!BO34 -> 0 | D19: =+Shepparton!#REF! -> #REF! | E19: =+Shepparton!#REF! -> #REF!
B20: =+'Fast Key'!A41 -> 0 | C20: =+'Fast Key'!BO41 -> 0 | D20: =+Shepparton!#REF! -> #REF! | E20: =+Shepparton!#REF! -> #REF!
B21: =+'Fast Key'!A42 -> 0 | C21: =+'Fast Key'!BO42 -> 0 | D21: =+Shepparton!#REF! -> #REF! | E21: =+Shepparton!#REF! -> #REF!
B22: =+'Fast Key'!A43 -> 0 | C22: =+'Fast Key'!BO43 -> 0 | D22: =+Shepparton!#REF! -> #REF! | E22: =+Shepparton!#REF! -> #REF!
B23: =+'Fast Key'!A44 -> 0 | C23: =+'Fast Key'!BO44 -> 0 | D23: =+Shepparton!#REF! -> #REF! | E23: =+Shepparton!#REF! -> #REF!
B24: =+'Fast Key'!A45 -> 0 | C24: =+'Fast Key'!BO45 -> 0 | D24: =+Shepparton!#REF! -> #REF! | E24: =+Shepparton!#REF! -> #REF!
B25: =+'Fast Key'!A46 -> 0 | C25: =+'Fast Key'!BO46 -> 0 | D25: =+Shepparton!#REF! -> #REF! | E25: =+Shepparton!#REF! -> #REF!
B26: =+'Fast Key'!A47 -> 0 | C26: =+'Fast Key'!BO47 -> 0 | D26: =+Shepparton!#REF! -> #REF! | E26: =+Shepparton!#REF! -> #REF!
B27: =+'Fast Key'!A48 -> 0 | C27: =+'Fast Key'!BO48 -> 0 | D27: =+Shepparton!#REF! -> #REF! | E27: =+Shepparton!#REF! -> #REF!
B28: =+'Fast Key'!A49 -> 0 | C28: =+'Fast Key'!BO49 -> 0 | D28: =+Shepparton!#REF! -> #REF! | E28: =+Shepparton!#REF! -> #REF!
B29: =+'Fast Key'!A50 -> 0 | C29: =+'Fast Key'!BO50 -> 0 | D29: =+Shepparton!#REF! -> #REF! | E29: =+Shepparton!#REF! -> #REF!
B30: =+'Fast Key'!A51 -> 0 | C30: =+'Fast Key'!BO51 -> 0 | D30: =+Shepparton!#REF! -> #REF! | E30: =+Shepparton!#REF! -> #REF!
B31: =+'Fast Key'!A52 -> 0 | C31: =+'Fast Key'!BO52 -> 0 | D31: =+Shepparton!#REF! -> #REF! | E31: =+Shepparton!#REF! -> #REF!
... B43: =+'Fast Key'!A64 -> 0 | C43: =+'Fast Key'!BO64 -> 0 | D43: =+Shepparton!#REF! -> #REF! | E43: =+Shepparton!#REF! -> #REF!
B44: =+'Fast Key'!A70 -> 0 | C44: =+'Fast Key'!BO70 -> 0 | D44: =+Shepparton!#REF! -> #REF! | E44: =+Shepparton!#REF! -> #REF!
B45: =+'Fast Key'!A71 -> 0 | C45: =+'Fast Key'!BO71 -> 0 | D45: =+Shepparton!#REF! -> #REF! | E45: =+Shepparton!#REF! -> #REF!
B46: =+'Fast Key'!A72 -> 0 | C46: =+'Fast Key'!BO72 -> 0 | D46: =+Shepparton!#REF! -> #REF! | E46: =+Shepparton!#REF! -> #REF!
B47: =+'Fast Key'!A73 -> 0 | C47: =+'Fast Key'!BO73 -> 0 | D47: =+Shepparton!#REF! -> #REF! | E47: =+Shepparton!#REF! -> #REF!
B48: =+'Fast Key'!A74 -> 0 | C48: =+'Fast Key'!BO74 -> 0 | D48: =+Shepparton!#REF! -> #REF! | E48: =+Shepparton!#REF! -> #REF!
